Workbook

Sheet 开票
A1: 深远5月材料开票清单（杭友开票） | D1: 做成 | E1: 财务 | F1: 原价 | G1: 外协
D2: 夏正芹
A3: 代码 | B3: 新代码 | C3: 材料名称 | D3: 数量 | E3: 单价 | F3: 金额
A4: =VLOOKUP(B:B,[1]原材料!$D$1:$E$65536,2,0) -> #N/A | B4: A1.1136 | C4: PA66+FG30 A104GH 6PS黑 | D4: 0 | E4: 24 | F4: =D4*E4 -> 0
A5: =VLOOKUP(B:B,[1]原材料!$D$1:$E$65536,2,0) -> A1.1530 | B5: A1.4214 | C5: APO 0816 HI JA6 BK | D5: 0 | E5: =VLOOKUP(A:A,[2]深远增税!$E$1:$Q$65536,13,0) -> 14.1 | F5: =D5*E5 -> 0
A6: =VLOOKUP(B:B,[1]原材料!$D$1:$E$65536,2,0) -> A1.1447 | B6: A1.4354 | C6: PA66 GF30 AKROMID A3 黑色 2385 | D6: 0 | E6: 34.39 | F6: =D6*E6 -> 0
A7: =VLOOKUP(B:B,[1]原材料!$D$1:$E$65536,2,0) -> A1.1678 | B7: A1.5193 | C7: PP A422 GM30RC（M） CB2685黑 | D7: 0 | E7: 10.26 | F7: =D7*E7 -> 0
A8: =VLOOKUP(B:B,[1]原材料!$D$1:$E$65536,2,0) -> #N/A | B8: F2.0380 | C8: 已全检标签 | D8: 0 | E8: 1.33 | F8: =D8*E8 -> 0
A9: =VLOOKUP(B:B,[1]原材料!$D$1:$E$65536,2,0) -> A1.1079 | B9: A1.4317 | C9: PA6 MG30 HSBK006 | D9: 6000 | E9: 17.8 | F9: =D9*E9 -> 106800
A10: A1.0973 | B10: A1.4093 | C10: ABS H02031B7 | D10: 0 | E10: 21.2 | F10: =D10*E10 -> 0
B11: F2.0363 | C11: 条码打印不干胶 | D11: 0 | E11: 20.51 | F11: =D11*E11 -> 0
B12: F2.0383 | C12: 标签不干胶 | D12: 0 | E12: 1.86 | F12: =D12*E12 -> 0
B13: F9.0462 | C13: 成形生产管理表 | D13: 5 | E13: 6.87 | F13: =D13*E13 -> 34.35
A14: =VLOOKUP(B:B,[1]原材料!$D$1:$E$65536,2,0) -> A1.1681 | B14: A1.5195 | C14: PP A422 LG30 B12378L黑 | D14: 0 | E14: =VLOOKUP(A:A,[2]深远增税!$E$1:$Q$65536,13,0) -> 13.5 | F14: =D14*E14 -> 0
A15: =VLOOKUP(B:B,[1]原材料!$D$1:$E$65536,2,0) -> A1.1511 | B15: A1.5328 | C15: PP HIFAX TYC 1152P BK | D15: 0 | E15: =VLOOKUP(A:A,[2]深远增税!$E$1:$Q$65536,13,0) -> 14.7 | F15: =D15*E15 -> 0
A16: =VLOOKUP(B:B,[1]原材料!$D$1:$E$65536,2,0) -> A1.1823 | B16: A1.5511 | C16: TPE AF 7210-70 ZHE 黑色 | D16: 0 | E16: 38 | F16: =D16*E16 -> 0
A17: =VLOOKUP(B:B,[1]原材料!$D$1:$E$65536,2,0) -> Z1.0435 | B17: F1.0411 | C17: E13864600 | D17: 18000 | E17: =VLOOKUP(A:A,[2]深远增税!$E$1:$Q$65536,13,0) -> 0.63 | F17: =D17*E17 -> 11340
A18: =VLOOKUP(B:B,[1]原材料!$D$1:$E$65536,2,0) -> Z1.0436 | B18: F1.0412 | C18: E13865200 | D18: 9000 | E18: =VLOOKUP(A:A,[2]深远增税!$E$1:$Q$65536,13,0) -> 0.77 | F18: =D18*E18 -> 6930
A19: =VLOOKUP(B:B,[1]原材料!$D$1:$E$65536,2,0) -> Z1.0448 | B19: F1.0415 | C19: E14383300（E10681900） | D19: 0 | E19: =VLOOKUP(A:A,[2]深远增税!$E$1:$Q$65536,13,0) -> 8.23 | F19: =D19*E19 -> 0
A20: =VLOOKUP(B:B,[1]原材料!$D$1:$E$65536,2,0) -> Z1.0450 | B20: F1.0416 | C20: E14383500（E10682100） | D20: 0 | E20: =VLOOKUP(A:A,[2]深远增税!$E$1:$Q$65536,13,0) -> 7.5 | F20: =D20*E20 -> 0
A21: =VLOOKUP(B:B,[1]原材料!$D$1:$E$65536,2,0) -> Z1.0449 | B21: F1.0417 | C21: E14383600（E10881800） | D21: 5000 | E21: =VLOOKUP(A:A,[2]深远增税!$E$1:$Q$65536,13,0) -> 0.88 | F21: =D21*E21 -> 4400
A22: =VLOOKUP(B:B,[1]原材料!$D$1:$E$65536,2,0) -> Z1.1314 | B22: F1.2115 | C22: 卡扣W714972-S300 | D22: 24000 | E22: =VLOOKUP(A:A,[2]深远增税!$E$1:$Q$65536,13,0) -> 0.13 | F22: =D22*E22 -> 3120
A23: =VLOOKUP(B:B,[1]原材料!$D$1:$E$65536,2,0) -> A1.1118 | B23: A1.4216 | C23: APO-308（PP-GF20%+MF10) BLACK | D23: 12000 | E23: =VLOOKUP(A:A,[2]深远增税!$E$1:$Q$65536,13,0) -> 10.9 | F23: =D23*E23 -> 130800
A24: =VLOOKUP(B:B,[1]原材料!$D$1:$E$65536,2,0) -> A1.1862 | B24: A1.4338 | C24: PA66 C200 BK121 | D24: 700 | E24: 31 | F24: =D24*E24 -> 21700
A25: Z1.0451 | B25: F1.0414 | C25: E14383000（E6679200） | D25: 6000 | E25: =VLOOKUP(A:A,[2]深远增税!$E$1:$Q$65536,13,0) -> 0.44 | F25: =D25*E25 -> 2640
A26: A1.1353 | B26: A1.4377 | C26: PA6-GF10-M20 | D26: 1600 | E26: 21 | F26: =D26*E26 -> 33600
B27: A1.6935 | C27: PA6 MG30 HSBK101黑色 | D27: 0 | E27: 21 | F27: =D27*E27 -> 0 | H27: 替代A1.4337
A28: Z1.0326 | B28: F1.0271 | C28: COVER PET覆膜 | D28: 14200 | E28: 0.53 | F28: =D28*E28 -> 7526
A29: =VLOOKUP(B:B,[1]原材料!$D$1:$E$65536,2,0) -> A1.0887 | B29: A1.4335 | C29: =VLOOKUP(B:B,[3]杭友!G:H,2,0) -> PA66 A3K NC | D29: 0 | E29: 35 | F29: =D29*E29 -> 0
A30: =VLOOKUP(B:B,[1]原材料!$D$1:$E$65536,2,0) -> A1.1806 | B30: A1.4425 | C30: =VLOOKUP(B:B,[3]杭友!G:H,2,0) -> PBT PET GF15 DSPBT-A001黑 | D30: 0 | E30: 13.3 | F30: =D30*E30 -> 0
A31: =VLOOKUP(B:B,[1]原材料!$D$1:$E$65536,2,0) -> A1.1680 | B31: A1.5228 | C31: =VLOOKUP(B:B,[3]杭友!G:H,2,0) -> PP C3322T M12F CB2685黑 | D31: 0 | E31: 11.6 | F31: =D31*E31 -> 0
A32: =VLOOKUP(B:B,[1]原材料!$D$1:$E$65536,2,0) -> Z1.0452 | B32: F1.0413 | C32: =VLOOKUP(B:B,[3]杭友!G:H,2,0) -> E14382900（E10629100） | D32: 6000 | E32: 0.38 | F32: =D32*E32 -> 2280
A33: =VLOOKUP(B:B,[1]原材料!$D$1:$E$65536,2,0) -> Z1.0453 | B33: F1.0418 | C33: =VLOOKUP(B:B,[3]杭友!G:H,2,0) -> E14383700（E11006400） | D33: 10400 | E33: 0.61 | F33: =D33*E33 -> 6344
A34: =VLOOKUP(B:B,[1]原材料!$D$1:$E$65536,2,0) -> #N/A | B34: AA.5388 | C34: PP/EPDM Santoprene 121-62M100 | D34: 0 | E34: 37.8 | F34: =D34*E34 -> 0
A35: =VLOOKUP(B:B,[1]原材料!$D$1:$E$65536,2,0) -> A1.1308 | B35: A1.5386 | C35: PP TYC852P C15715 YZ9 | D35: 0 | E35: 14.4 | F35: =D35*E35 -> 0
A36: =VLOOKUP(B:B,[1]原材料!$D$1:$E$65536,2,0) -> A1.1119 | B36: A1.4217 | C36: APO-308（PP-GF20%+MF10) WHITE | D36: 0 | E36: 10.9 | F36: =D36*E36 -> 0
B37: A1.5380 | C37: PP TD17 BMV214W10609M | D37: 1000 | E37: 10.7 | F37: =D37*E37 -> 10700
A38: =VLOOKUP(B:B,[1]原材料!$D$1:$E$65536,2,0) -> Z1.1533 | B38: F1.1956 | C38: 圆柱嵌件32055435T | D38: 0 | E38: 0.4 | F38: =D38*E38 -> 0
A39: =VLOOKUP(B:B,[1]原材料!$D$1:$E$65536,2,0) -> Z2.113 | B39: F2.0189 | C39: 文兴清洗剂 | D39: 0 | E39: 9.4 | F39: =D39*E39 -> 0
B40: F2.0190 | C40: 文兴脱膜剂 | D40: 0 | E40: 8.72 | F40: =D40*E40 -> 0
...

Sheet Sheet2
A3: 图号 | B3: 求和项:业务数量
A4: A1.4216 | B4: 12000 | D4: =SUMIF(开票!B:B,A:A,开票!D:D) -> 12000
A5: A1.4317 | B5: 6000 | D5: =SUMIF(开票!B:B,A:A,开票!D:D) -> 6000
A6: A1.4338 | B6: 700 | D6: =SUMIF(开票!B:B,A:A,开票!D:D) -> 700
A7: A1.4377 | B7: 1600 | D7: =SUMIF(开票!B:B,A:A,开票!D:D) -> 1600
A8: A1.5226 | B8: 1000 | D8: =SUMIF(开票!B:B,A:A,开票!D:D) -> 1000
A9: A1.5357 | B9: 1000 | D9: =SUMIF(开票!B:B,A:A,开票!D:D) -> 1000
A10: A1.5358 | B10: 200 | D10: =SUMIF(开票!B:B,A:A,开票!D:D) -> 200
A11: A1.5380 | B11: 1000 | D11: =SUMIF(开票!B:B,A:A,开票!D:D) -> 1000
A12: A1.5413 | B12: 110 | D12: =SUMIF(开票!B:B,A:A,开票!D:D) -> 110
A13: A1.6618 | B13: 2000 | D13: =SUMIF(开票!B:B,A:A,开票!D:D) -> 2000
A14: A1.6621 | B14: 1825 | D14: =SUMIF(开票!B:B,A:A,开票!D:D) -> 1825
A15: F1.0271 | B15: 14200 | D15: =SUMIF(开票!B:B,A:A,开票!D:D) -> 14200
... A35: F9.0495 | B35: 80 | D35: =SUMIF(开票!B:B,A:A,开票!D:D) -> 80
A36: 总计 | B36: 196200

Sheet Sheet1
A1: 单据号 | B1: 单据类型 | C1: 仓库编码 | D1: 仓库名 | E1: 供应商 | F1: 客户 | G1: 结算客户 | H1: 品号类型 | I1: 品号 | J1: 品名 | K1: 图号 | L1: 二级类别 | M1: 装箱数 | N1: 箱数 | O1: 业务数量 | P1: 托码 | Q1: 库位编号 | R1: 批号 | S1: 批号描述 | T1: 生产日期 | U1: 流转卡号 | V1: 单据备注 | W1: 备注 | X1: 部门 | Y1: 操作人 | Z1: 操作时间 | AA1: 方向 | AB1: 出入库时间 | AC1: 规格 | AD1: 单位
A2: 1309-202605290002 | B2: 材料销货出库单 | C2: 02 | D2: 原材料扫码仓 | F2: W10 | G2: W10 | H2: 采购件 | I2: 3100635 | J2: PA6-GF10-M20 | K2: A1.4377 | L2: 塑料粒子 | M2: 1600 | N2: 1 | O2: 1600 | P2: T02*604681 | Q2: 001-1-1 | R2: 2026052948 | S2: 0126607601 | T2: 2026/05/29 | V2: 4747155 | X2: 控股及其他属地 | Y2: 丰金册 | Z2: 2026/05/29 | AA2: 出库 | AB2: 2026/05/29 20:30:54 | AD2: KG
A3: 1309-202605290002 | B3: 材料销货出库单 | C3: 02 | D3: 原材料扫码仓 | F3: W10 | G3: W10 | H3: 采购件 | I3: 15003103143 | J3: PP LGF40 P707LG BK黑色 | K3: A1.6621 | L3: 塑料粒子 | M3: 825 | N3: 1 | O3: 825 | P3: T02*564513 | Q3: D08-3-1 | R3: 2026032415 | S3: 260313XB | T3: 2026/05/02 | V3: 4747155 | X3: 控股及其他属地 | Y3: 左文明 | Z3: 2026/05/29 | AA3: 出库 | AB3: 2026/05/29 18:29:51 | AC3: 增税 | AD3: KG
A4: 1309-202605290002 | B4: 材料销货出库单 | C4: 02 | D4: 原材料扫码仓 | F4: W10 | G4: W10 | H4: 采购件 | I4: 15003103143 | J4: PP LGF40 P707LG BK黑色 | K4: A1.6621 | L4: 塑料粒子 | M4: 25 | N4: 40 | O4: 1000 | P4: T02*543554 | Q4: A15-3-2 | R4: 2026033128 | S4: 260324XB | T4: 2026/03/31 | V4: 4747155 | X4: 控股及其他属地 | Y4: 左文明 | Z4: 2026/05/29 | AA4: 出库 | AB4: 2026/05/29 18:26:12 | AC4: 增税 | AD4: KG
A5: 1309-202605290002 | B5: 材料销货出库单 | C5: 02 | D5: 原材料扫码仓 | F5: W10 | G5: W10 | H5: 采购件 | I5: 3101142 | J5: PP TD17 BMV214W10609M | K5: A1.5380 | L5: 塑料粒子 | M5: 25 | N5: 40 | O5: 1000 | P5: T02*558794 | Q5: B06-4-2 | R5: 2026041101 | S5: M260411521 | T5: 2026/04/11 | V5: 4747155 | X5: 控股及其他属地 | Y5: 左文明 | Z5: 2026/05/29 | AA5: 出库 | AB5: 2026/05/29 18:24:47 | AC5: 增税 | AD5: KG
A6: 1290-202605290006 | B6: MES总务领料单 | C6: 05 | D6: 总务仓库 | F6: W10 | G6: W10 | H6: 采购件 | I6: 5100094 | J6: 成形生产管理表 | K6: F9.0462 | L6: 生产性辅助材料 | M6: 110 | N6: 0 | O6: 5 | P6: T02**10034 | Q6: 001-1-8 | R6: 20241018 | S6: 20241016 | T6: 2024/10/16 | V6: 4746983 | X6: 控股及其他属地 | Y6: 高佳丹 | Z6: 2026/05/29 | AA6: 出库 | AB6: 2026/05/29 10:57:13 | AC6: 增税 | AD6: 本
A7: 1309-202605250002 | B7: 材料销货出库单 | C7: 105 | D7: 辅件扫码仓 | F7: W10 | G7: W10 | H7: 采购件 | I7: 3600742 | J7: 卡扣W717086-S439(539B4002AA0) | K7: F1.1538 | L7: 辅件 | M7: 5000 | N7: 1 | O7: 3000 | P7: T02**61521 | Q7: B04-1-1 | R7: 2023100838 | S7: 20231119 | T7: 2023/10/08 | V7: 4747152 | X7: 控股及其他属地 | Y7: 张国艳 | Z7: 2026/05/25 | AA7: 出库 | AB7: 2026/05/25 19:11:18 | AC7: 增税 | AD7: PCS
A8: 1309-202605250002 | B8: 材料销货出库单 | C8: 105 | D8: 辅件扫码仓 | F8: W10 | G8: W10 | H8: 采购件 | I8: 15003662599 | J8: 泡棉T15*29.5*32.9mm(70644001AA0) | K8: F1.2862 | L8: 辅件 | M8: 2000 | N8: 1 | O8: 2000 | P8: T02**61285 | Q8: A02-2-4 | R8: 2026051939 | S8: 20260514 | T8: 2026/05/19 | V8: 4747152 | X8: 控股及其他属地 | Y8: 张国艳 | Z8: 2026/05/25 | AA8: 出库 | AB8: 2026/05/25 18:00:12 | AC8: 增税 | AD8: PCS
A9: 1309-202605250002 | B9: 材料销货出库单 | C9: 105 | D9: 辅件扫码仓 | F9: W10 | G9: W10 | H9: 采购件 | I9: 15003662599 | J9: 泡棉T15*29.5*32.9mm(70644001AA0) | K9: F1.2862 | L9: 辅件 | M9: 2000 | N9: 1 | O9: 2000 | P9: T02**61275 | Q9: B02-1-1 | R9: 2026043064 | S9: 20260429 | T9: 2026/04/30 | V9: 4747152 | X9: 控股及其他属地 | Y9: 张国艳 | Z9: 2026/05/25 | AA9: 出库 | AB9: 2026/05/25 18:00:05 | AC9: 增税 | AD9: PCS
A10: 1309-202605250002 | B10: 材料销货出库单 | C10: 105 | D10: 辅件扫码仓 | F10: W10 | G10: W10 | H10: 采购件 | I10: 15003662601 | J10: 泡棉T3*5*50mm(70644003AA0) | K10: F1.2864 | L10: 辅件 | M10: 2000 | N10: 1 | O10: 2000 | P10: T02**61280 | Q10: B12-1-2 | R10: 2026051937 | S10: 20260518 | T10: 2026/05/19 | V10: 4747152 | X10: 控股及其他属地 | Y10: 张国艳 | Z10: 2026/05/25 | AA10: 出库 | AB10: 2026/05/25 17:59:51 | AC10: 增税 | AD10: PCS
A11: 1309-202605250002 | B11: 材料销货出库单 | C11: 105 | D11: 辅件扫码仓 | F11: W10 | G11: W10 | H11: 采购件 | I11: 15003662601 | J11: 泡棉T3*5*50mm(70644003AA0) | K11: F1.2864 | L11: 辅件 | M11: 2000 | N11: 1 | O11: 2000 | P11: T02**61280 | Q11: B12-1-2 | R11: 2026043065 | S11: 20260429 | T11: 2026/04/30 | V11: 4747152 | X11: 控股及其他属地 | Y11: 张国艳 | Z11: 2026/05/25 | AA11: 出库 | AB11: 2026/05/25 17:59:45 | AC11: 增税 | AD11: PCS
A12: 1309-202605250002 | B12: 材料销货出库单 | C12: 105 | D12: 辅件扫码仓 | F12: W10 | G12: W10 | H12: 采购件 | I12: 15003662600 | J12: 泡棉T5*13*85mm(70644002AA0) | K12: F1.2863 | L12: 辅件 | M12: 2000 | N12: 1 | O12: 2000 | P12: T02**61280 | Q12: B12-1-2 | R12: 2026051938 | S12: 20260518 | T12: 2026/05/19 | V12: 4747152 | X12: 控股及其他属地 | Y12: 张国艳 | Z12: 2026/05/25 | AA12: 出库 | AB12: 2026/05/25 17:59:24 | AC12: 增税 | AD12: PCS
A13: 1309-202605250002 | B13: 材料销货出库单 | C13: 105 | D13: 辅件扫码仓 | F13: W10 | G13: W10 | H13: 采购件 | I13: 15003662600 | J13: 泡棉T5*13*85mm(70644002AA0) | K13: F1.2863 | L13: 辅件 | M13: 2000 | N13: 1 | O13: 2000 | P13: T02**61287 | Q13: B02-2-2 | R13: 2026043062 | S13: 20260429 | T13: 2026/04/30 | V13: 4747152 | X13: 控股及其他属地 | Y13: 张国艳 | Z13: 2026/05/25 | AA13: 出库 | AB13: 2026/05/25 17:59:17 | AC13: 增税 | AD13: PCS
A14: 1309-202605250002 | B14: 材料销货出库单 | C14: 105 | D14: 辅件扫码仓 | F14: W10 | G14: W10 | H14: 采购件 | I14: 3600742 | J14: 卡扣W717086-S439(539B4002AA0) | K14: F1.1538 | L14: 辅件 | M14: 5000 | N14: 1 | O14: 5000 | P14: T02**61509 | Q14: A02-1-2 | R14: 2026050853 | S14: 20260429 | T14: 2026/05/08 | V14: 4747152 | X14: 控股及其他属地 | Y14: 张国艳 | Z14: 2026/05/25 | AA14: 出库 | AB14: 2026/05/25 17:58:54 | AC14: 增税 | AD14: PCS
... A17: 1309-202605250002 | B17: 材料销货出库单 | C17: 105 | D17: 辅件扫码仓 | F17: W10 | G17: W10 | H17: 采购件 | I17: 3600742 | J17: 卡扣W717086-S439(539B4002AA0) | K17: F1.1538 | L17: 辅件 | M17: 10000 | N17: 1 | O17: 10000 | P17: T02**61274 | Q17: A01-1-4 | R17: 2026042702 | S17: 20260226 | T17: 2026/04/27 | V17: 4747152 | X17: 控股及其他属地 | Y17: 张国艳 | Z17: 2026/05/25 | AA17: 出库 | AB17: 2026/05/25 17:58:17 | AC17: 增税 | AD17: PCS
A18: 1309-202605190004 | B18: 材料销货出库单 | C18: 02 | D18: 原材料扫码仓 | F18: W10 | G18: W10 | H18: 采购件 | I18: 3100262 | J18: APO-308（PP-GF20%+MF10) BLACK | K18: A1.4216 | L18: 塑料粒子 | M18: 3000 | N18: 1 | O18: 3000 | P18: T02*596264 | Q18: 001-1-1 | R18: 2026051912 | S18: 31402142 | T18: 2026/05/19 | V18: 4746143 | X18: 控股及其他属地 | Y18: 左文明 | Z18: 2026/05/19 | AA18: 出库 | AB18: 2026/05/19 18:16:00 | AD18: KG
A19: 1309-202605190004 | B19: 材料销货出库单 | C19: 02 | D19: 原材料扫码仓 | F19: W10 | G19: W10 | H19: 采购件 | I19: 3100247 | J19: PA6 MG30 HSBK006 | K19: A1.4317 | L19: 塑料粒子 | M19: 3000 | N19: 1 | O19: 3000 | P19: T02*596264 | Q19: 001-1-1 | R19: 2026051907 | S19: 51756411 | T19: 2026/05/19 | V19: 4746143 | X19: 控股及其他属地 | Y19: 左文明 | Z19: 2026/05/19 | AA19: 出库 | AB19: 2026/05/19 18:15:55 | AD19: KG
A20: 1309-202605180003 | B20: 材料销货出库单 | C20: 105 | D20: 辅件扫码仓 | F20: W10 | G20: W10 | H20: 采购件 | I20: 15003602043 | J20: Y0801426-INSERT METAL | K20: F1.2377 | L20: 生产性辅助材料 | M20: 3000 | N20: 1 | O20: 3000 | P20: T02**14728 | Q20: B11-1-3 | R20: 2026051642 | S20: 20260428 | T20: 2026/05/16 | V20: 4746142 | X20: 控股及其他属地 | Y20: 张国艳 | Z20: 2026/05/18 | AA20: 出库 | AB20: 2026/05/18 12:56:46 | AC20: 增税 | AD20: PCS
A21: 1309-202605180003 | B21: 材料销货出库单 | C21: 105 | D21: 辅件扫码仓 | F21: W10 | G21: W10 | H21: 采购件 | I21: 3600165 | J21: 卡扣W714972-S300 | K21: F1.2115 | L21: 辅件 | M21: 24000 | N21: 1 | O21: 24000 | P21: T02**61274 | Q21: A01-2-2 | R21: 2026040356 | S21: 202601009-3 | T21: 2026/04/03 | V21: 4746142 | X21: 控股及其他属地 | Y21: 张国艳 | Z21: 2026/05/18 | AA21: 出库 | AB21: 2026/05/18 12:55:54 | AD21: PCS
A22: 1309-202605180003 | B22: 材料销货出库单 | C22: 105 | D22: 辅件扫码仓 | F22: W10 | G22: W10 | H22: 采购件 | I22: 3600725 | J22: 毛毡 50*10*0.5 | K22: F1.1592 | L22: 辅件 | M22: 4000 | N22: 1 | O22: 4000 | P22: T02**61525 | Q22: B04-2-1 | R22: 2026043043 | S22: 20260429 | T22: 2026/04/30 | V22: 4746142 | X22: 控股及其他属地 | Y22: 张国艳 | Z22: 2026/05/18 | AA22: 出库 | AB22: 2026/05/18 12:55:21 | AC22: 增税 | AD22: PCS
A23: 1309-202605180003 | B23: 材料销货出库单 | C23: 105 | D23: 辅件扫码仓 | F23: W10 | G23: W10 | H23: 采购件 | I23: 3600688 | J23: Flocked Tape 毛毡 30*17*1 | K23: F1.0858 | L23: 辅件 | M23: 1000 | N23: 1 | O23: 1000 | P23: T02**61525 | Q23: B04-2-1 | R23: 2025112927 | S23: 20051128 | T23: 2025/11/29 | V23: 4746142 | X23: 控股及其他属地 | Y23: 张国艳 | Z23: 2026/05/18 | AA23: 出库 | AB23: 2026/05/18 12:54:12 | AC23: 增税 | AD23: PCS
A24: 1309-202605150006 | B24: 材料销货出库单 | C24: 02 | D24: 原材料扫码仓 | F24: W10 | G24: W10 | H24: 采购件 | I24: 3100262 | J24: APO-308（PP-GF20%+MF10) BLACK | K24: A1.4216 | L24: 塑料粒子 | M24: 2700 | N24: 1 | O24: 2700 | P24: T02*467536 | Q24: 001-1-1 | R24: 2026051507 | S24: 31402142 | T24: 2026/05/15 | V24: 4746141 | X24: 控股及其他属地 | Y24: 左文明 | Z24: 2026/05/15 | AA24: 出库 | AB24: 2026/05/15 17:43:13 | AD24: KG
A25: 1309-202605150006 | B25: 材料销货出库单 | C25: 02 | D25: 原材料扫码仓 | F25: W10 | G25: W10 | H25: 采购件 | I25: 3100262 | J25: APO-308（PP-GF20%+MF10) BLACK | K25: A1.4216 | L25: 塑料粒子 | M25: 300 | N25: 1 | O25: 300 | P25: T02*467536 | Q25: 001-1-1 | R25: 2026051508 | S25: 31401466 | T25: 2026/05/15 | V25: 4746141 | X25: 控股及其他属地 | Y25: 左文明 | Z25: 2026/05/15 | AA25: 出库 | AB25: 2026/05/15 17:42:40 | AD25: KG
A26: 1309-202605120008 | B26: 材料销货出库单 | C26: 105 | D26: 辅件扫码仓 | F26: W10 | G26: W10 | H26: 采购件 | I26: 3600444 | J26: COVER PET覆膜 | K26: F1.0271 | L26: 辅件 | M26: 14200 | N26: 1 | O26: 14200 | P26: T02**29245 | Q26: D05-2-3 | R26: 2026051001 | S26: 20260509 | T26: 2026/05/10 | V26: 4746139 | X26: 控股及其他属地 | Y26: 张国艳 | Z26: 2026/05/12 | AA26: 出库 | AB26: 2026/05/12 19:56:29 | AD26: PCS
A27: 1309-202605110006 | B27: 材料销货出库单 | C27: 02 | D27: 原材料扫码仓 | F27: W10 | G27: W10 | H27: 采购件 | I27: 15003103140 | J27: PP TD20 BK黑色 | K27: A1.6618 | L27: 塑料粒子 | M27: 1000 | N27: 1 | O27: 875 | P27: T02*574292 | Q27: 001-1-1 | R27: 2026042626 | S27: 2603060001 | T27: 2026/04/26 | V27: 4746138 | X27: 控股及其他属地 | Y27: 丰金册 | Z27: 2026/05/11 | AA27: 出库 | AB27: 2026/05/11 13:12:20 | AC27: 增税 | AD27: KG
A28: 1309-202605110006 | B28: 材料销货出库单 | C28: 02 | D28: 原材料扫码仓 | F28: W10 | G28: W10 | H28: 采购件 | I28: 15003103140 | J28: PP TD20 BK黑色 | K28: A1.6618 | L28: 塑料粒子 | M28: 1000 | N28: 0 | O28: 125 | P28: T02*558378 | Q28: 001-1-1 | R28: 2026040951 | S28: 2603060001 | T28: 2026/04/09 | V28: 4746138 | X28: 控股及其他属地 | Y28: 丰金册 | Z28: 2026/05/11 | AA28: 出库 | AB28: 2026/05/11 13:11:36 | AC28: 增税 | AD28: KG
A29: 1309-202605110006 | B29: 材料销货出库单 | C29: 02 | D29: 原材料扫码仓 | F29: W10 | G29: W10 | H29: 采购件 | I29: 3101137 | J29: PP T20 A5132T-729-A3 EA9 CB1690黑 | K29: A1.5357 | L29: 塑料粒子 | M29: 1000 | N29: 1 | O29: 1000 | P29: T02*566393 | Q29: B18-3-2 | R29: 2026042234 | S29: 260401 | T29: 2026/04/22 | V29: 4746138 | X29: 控股及其他属地 | Y29: 丰金册 | Z29: 2026/05/11 | AA29: 出库 | AB29: 2026/05/11 12:59:43 | AC29: 增税 | AD29: KG
A30: 1309-202605110006 | B30: 材料销货出库单 | C30: 02 | D30: 原材料扫码仓 | F30: W10 | G30: W10 | H30: 采购件 | I30: 15003103140 | J30: PP TD20 BK黑色 | K30: A1.6618 | L30: 塑料粒子 | M30: 1000 | N30: 1 | O30: 1000 | P30: T02*558378 | Q30: 001-1-1 | R30: 2026040951 | S30: 2603060001 | T30: 2026/04/09 | V30: 4746138 | X30: 控股及其他属地 | Y30: 丰金册 | Z30: 2026/05/11 | AA30: 出库 | AB30: 2026/05/11 12:55:30 | AC30: 增税 | AD30: KG
A31: 1309-202605110006 | B31: 材料销货出库单 | C31: 02 | D31: 原材料扫码仓 | F31: W10 | G31: W10 | H31: 采购件 | I31: 3101145 | J31: PP C3322T B18(UV) JA6 | K31: A1.5226 | L31: 塑料粒子 | M31: 25 | N31: 40 | O31: 1000 | P31: T02*561530 | Q31: D11-1-2 | R31: 2026041331 | S31: 260401 | T31: 2026/04/13 | V31: 4746138 | X31: 控股及其他属地 | Y31: 丰金册 | Z31: 2026/05/11 | AA31: 出库 | AB31: 2026/05/11 12:55:09 | AC31: 增税 | AD31: KG
A32: 1309-202605080001 | B32: 材料销货出库单 | C32: 02 | D32: 原材料扫码仓 | F32: W10 | G32: W10 | H32: 采购件 | I32: 3100262 | J32: APO-308（PP-GF20%+MF10) BLACK | K32: A1.4216 | L32: 塑料粒子 | M32: 1825 | N32: 1 | O32: 1825 | P32: T02*583947 | Q32: 001-1-1 | R32: 2026050727 | S32: 31397241 | T32: 2026/05/07 | V32: 4746137 | X32: 控股及其他属地 | Y32: 丰金册 | Z32: 2026/05/09 | AA32: 出库 | AB32: 2026/05/09 15:35:11 | AD32: KG
A33: 1309-202605080001 | B33: 材料销货出库单 | C33: 02 | D33: 原材料扫码仓 | F33: W10 | G33: W10 | H33: 采购件 | I33: 3100262 | J33: APO-308（PP-GF20%+MF10) BLACK | K33: A1.4216 | L33: 塑料粒子 | M33: 4175 | N33: 1 | O33: 4175 | P33: T02*583947 | Q33: 001-1-1 | R33: 2026050726 | S33: 31401466 | T33: 2026/05/07 | V33: 4746137 | X33: 控股及其他属地 | Y33: 丰金册 | Z33: 2026/05/09 | AA33: 出库 | AB33: 2026/05/09 15:34:59 | AD33: KG
A34: 1309-202605080001 | B34: 材料销货出库单 | C34: 02 | D34: 原材料扫码仓 | F34: W10 | G34: W10 | H34: 采购件 | I34: 3100247 | J34: PA6 MG30 HSBK006 | K34: A1.4317 | L34: 塑料粒子 | M34: 3000 | N34: 1 | O34: 3000 | P34: T02*584035 | Q34: 001-1-1 | R34: 2026050829 | S34: 51756411 | T34: 2026/05/09 | V34: 4746137 | X34: 控股及其他属地 | Y34: 丰金册 | Z34: 2026/05/09 | AA34: 出库 | AB34: 2026/05/09 15:34:44 | AD34: KG
A35: 1309-202605080001 | B35: 材料销货出库单 | C35: 02 | D35: 原材料扫码仓 | F35: W10 | G35: W10 | H35: 采购件 | I35: 3101115 | J35: PA66 C200 BK121 | K35: A1.4338 | L35: 塑料粒子 | M35: 25 | N35: 28 | O35: 700 | P35: T02*583441 | Q35: C05-3-2 | R35: 2026050738 | S35: 51724339 | T35: 2026/05/07 | V35: 4746137 | X35: 控股及其他属地 | Y35: 丰金册 | Z35: 2026/05/09 | AA35: 出库 | AB35: 2026/05/09 15:34:34 | AC35: 增税 | AD35: KG
A36: 1309-202605080001 | B36: 材料销货出库单 | C36: 02 | D36: 原材料扫码仓 | F36: W10 | G36: W10 | H36: 采购件 | I36: 3101138 | J36: PP T20 A5132T-729-A3 JM8 SH4865灰 | K36: A1.5358 | L36: 塑料粒子 | M36: 25 | N36: 8 | O36: 200 | P36: T02*506156 | Q36: A15-2-1 | R36: 2025120841 | S36: 01618-556034 | T36: 2025/12/08 | V36: 4746137 | X36: 控股及其他属地 | Y36: 丰金册 | Z36: 2026/05/09 | AA36: 出库 | AB36: 2026/05/09 15:34:24 | AC36: 增税 | AD36: KG
A37: 1309-202605060008 | B37: 材料销货出库单 | C37: 02 | D37: 原材料扫码仓 | F37: W10 | G37: W10 | H37: 采购件 | I37: 3101082 | J37: PP T20 P20T20A10-LE-CS(EF1E)碳黑 | K37: A1.5413 | L37: 塑料粒子 | M37: 110 | N37: 1 | O37: 110 | P37: T02*467536 | Q37: 001-1-1 | R37: 2026041201 | S37: 26040801 | T37: 2026/04/30 | V37: 4746966 | X37: 控股及其他属地 | Y37: 丰金册 | Z37: 2026/05/07 | AA37: 出库 | AB37: 2026/05/07 14:49:21 | AC37: 增税 | AD37: KG
A38: 1290-202605060016 | B38: MES总务领料单 | C38: 05 | D38: 总务仓库 | F38: W10 | G38: W10 | H38: 采购件 | I38: 15005302785 | J38: 麦格纳明细书 | K38: F9.0495 | L38: 生产性辅助材料 | M38: 80 | N38: 1 | O38: 80 | P38: T02**10034 | Q38: 001-1-7 | R38: 20260331 | S38: 20260328 | T38: 2026/03/28 | V38: 4746974 | X38: 控股及其他属地 | Y38: 高佳丹 | Z38: 2026/05/07 | AA38: 出库 | AB38: 2026/05/07 10:09:21 | AC38: 增税 | AD38: 本
A39: 1309-202605060007 | B39: 材料销货出库单 | C39: 105 | D39: 辅件扫码仓 | F39: W10 | G39: W10 | H39: 采购件 | I39: 3601932 | J39: 麦拉片 27*19*0.2 | K39: F1.2287 | L39: 辅件 | M39: 4000 | N39: 1 | O39: 4000 | P39: T02**61525 | Q39: B04-2-1 | R39: 2026043048 | S39: 20260429 | T39: 2026/04/30 | V39: 4746965 | X39: 控股及其他属地 | Y39: 张国艳 | Z39: 2026/05/06 | AA39: 出库 | AB39: 2026/05/06 19:33:21 | AC39: 增税 | AD39: PCS
A40: 1309-202605060007 | B40: 材料销货出库单 | C40: 105 | D40: 辅件扫码仓 | F40: W10 | G40: W10 | H40: 采购件 | I40: 3600723 | J40: 左侧吸音棉 156*137*15 | K40: F1.2108 | L40: 辅件 | M40: 2000 | N40: 1 | O40: 2000 | P40: T02**29245 | Q40: D05-2-3 | R40: 2026043042 | S40: 20260429 | T40: 2026/04/30 | V40: 4746965 | X40: 控股及其他属地 | Y40: 张国艳 | Z40: 2026/05/06 | AA40: 出库 | AB40: 2026/05/06 19:31:43 | AC40: 增税 | AD40: PCS
A41: 1309-202605060006 | B41: 材料销货出库单 | C41: 105 | D41: 辅件扫码仓 | F41: W10 | G41: W10 | H41: 采购件 | I41: 3600554 | J41: E13865200 | K41: F1.0412 | L41: 辅件 | M41: 9000 | N41: 1 | O41: 9000 | P41: T02**29245 | Q41: D05-2-3 | R41: 2026050329 | S41: CF07BNAHH | T41: 2026/05/03 | V41: 4746964 | X41: 控股及其他属地 | Y41: 张国艳 | Z41: 2026/05/06 | AA41: 出库 | AB41: 2026/05/06 19:30:33 | AD41: PCS
A42: 1309-202605060006 | B42: 材料销货出库单 | C42: 105 | D42: 辅件扫码仓 | F42: W10 | G42: W10 | H42: 采购件 | I42: 3600553 | J42: E13864600 | K42: F1.0411 | L42: 辅件 | M42: 18000 | N42: 1 | O42: 18000 | P42: T02**29245 | Q42: D05-2-3 | R42: 2026050328 | S42: CF0NSYAH | T42: 2026/05/03 | V42: 4746964 | X42: 控股及其他属地 | Y42: 张国艳 | Z42: 2026/05/06 | AA42: 出库 | AB42: 2026/05/06 19:30:26 | AD42: PCS
...

Sheet 2023年10月材料用              
A1: 2023年9月份深远材料辅件领用清单
A2: 材料代码 | B2: 日期 数量 名称 | C2: 45205 | D2: 45208 | E2: 45209 | F2: 45211 | G2: 45212 | H2: 45215 | I2: 45216 | J2: 45218 | K2: 45222 | L2: 45223 | M2: 45225 | N2: 45229 | BN2: 深远 | BO2: 杭友
A3: A1.1811 | B3: PP-CGF+TD235 | BN3: =BM3+BL3+BK3+BJ3+BI3+BH3+BG3+BF3+BE3+BD3+BC3+BB3+BA3+AZ3+AY3+AX3+AW3+AV3+AU3+AT3+AS3+AR3+AQ3+AP3+AO3+AN3+AM3+AL3+AK3+AJ3+AI3+AH3+AG3+AF3+AE3+AD3+AC3+AB3+AA3+Z3+Y3+X3+W3+V3+U3+T3+S3+R3+Q3+P3+O3+N3+M3+L3+K3+J3+I3+H3+G3+F3+E3+D3+C3 -> 0
A4: A1.1812 | B4: PA6 BKV60HZ.0WSS | BN4: =BM4+BL4+BK4+BJ4+BI4+BH4+BG4+BF4+BE4+BD4+BC4+BB4+BA4+AZ4+AY4+AX4+AW4+AV4+AU4+AT4+AS4+AR4+AQ4+AP4+AO4+AN4+AM4+AL4+AK4+AJ4+AI4+AH4+AG4+AF4+AE4+AD4+AC4+AB4+AA4+Z4+Y4+X4+W4+V4+U4+T4+S4+R4+Q4+P4+O4+N4+M4+L4+K4+J4+I4+H4+G4+F4+E4+D4+C4 -> 0
A5: A1.1131 | B5: PA66-FG30A104GH | BN5: =BM5+BL5+BK5+BJ5+BI5+BH5+BG5+BF5+BE5+BD5+BC5+BB5+BA5+AZ5+AY5+AX5+AW5+AV5+AU5+AT5+AS5+AR5+AQ5+AP5+AO5+AN5+AM5+AL5+AK5+AJ5+AI5+AH5+AG5+AF5+AE5+AD5+AC5+AB5+AA5+Z5+Y5+X5+W5+V5+U5+T5+S5+R5+Q5+P5+O5+N5+M5+L5+K5+J5+I5+H5+G5+F5+E5+D5+C5 -> 0
A6: A5.4332 | B6: PA66 101LNC010 | BN6: =BM6+BL6+BK6+BJ6+BI6+BH6+BG6+BF6+BE6+BD6+BC6+BB6+BA6+AZ6+AY6+AX6+AW6+AV6+AU6+AT6+AS6+AR6+AQ6+AP6+AO6+AN6+AM6+AL6+AK6+AJ6+AI6+AH6+AG6+AF6+AE6+AD6+AC6+AB6+AA6+Z6+Y6+X6+W6+V6+U6+T6+S6+R6+Q6+P6+O6+N6+M6+L6+K6+J6+I6+H6+G6+F6+E6+D6+C6 -> 0
A7: A1.4335 | B7: PA66 A3K NC | BN7: =BM7+BL7+BK7+BJ7+BI7+BH7+BG7+BF7+BE7+BD7+BC7+BB7+BA7+AZ7+AY7+AX7+AW7+AV7+AU7+AT7+AS7+AR7+AQ7+AP7+AO7+AN7+AM7+AL7+AK7+AJ7+AI7+AH7+AG7+AF7+AE7+AD7+AC7+AB7+AA7+Z7+Y7+X7+W7+V7+U7+T7+S7+R7+Q7+P7+O7+N7+M7+L7+K7+J7+I7+H7+G7+F7+E7+D7+C7 -> 0
A8: A1.4338 | B8: PA66 C200 BK121 | L8: 1000 | BN8: =BM8+BL8+BK8+BJ8+BI8+BH8+BG8+BF8+BE8+BD8+BC8+BB8+BA8+AZ8+AY8+AX8+AW8+AV8+AU8+AT8+AS8+AR8+AQ8+AP8+AO8+AN8+AM8+AL8+AK8+AJ8+AI8+AH8+AG8+AF8+AE8+AD8+AC8+AB8+AA8+Z8+Y8+X8+W8+V8+U8+T8+S8+R8+Q8+P8+O8+N8+M8+L8+K8+J8+I8+H8+G8+F8+E8+D8+C8 -> 1000
A9: A1.4354 | B9: PA66GF30AKROM117 | BN9: =BM9+BL9+BK9+BJ9+BI9+BH9+BG9+BF9+BE9+BD9+BC9+BB9+BA9+AZ9+AY9+AX9+AW9+AV9+AU9+AT9+AS9+AR9+AQ9+AP9+AO9+AN9+AM9+AL9+AK9+AJ9+AI9+AH9+AG9+AF9+AE9+AD9+AC9+AB9+AA9+Z9+Y9+X9+W9+V9+U9+T9+S9+R9+Q9+P9+O9+N9+M9+L9+K9+J9+I9+H9+G9+F9+E9+D9+C9 -> 0
A10: A1.4377 | B10: PA6 ALCOM GF10 | F10: 800 | G10: 1600 | H10: 800 | BN10: =BM10+BL10+BK10+BJ10+BI10+BH10+BG10+BF10+BE10+BD10+BC10+BB10+BA10+AZ10+AY10+AX10+AW10+AV10+AU10+AT10+AS10+AR10+AQ10+AP10+AO10+AN10+AM10+AL10+AK10+AJ10+AI10+AH10+AG10+AF10+AE10+AD10+AC10+AB10+AA10+Z10+Y10+X10+W10+V10+U10+T10+S10+R10+Q10+P10+O10+N10+M10+L10+K10+J10+I10+H10+G10+F10+E10+D10+C10 -> 3200
A11: A1.4404 | B11: PBTGFH | BN11: =BM11+BL11+BK11+BJ11+BI11+BH11+BG11+BF11+BE11+BD11+BC11+BB11+BA11+AZ11+AY11+AX11+AW11+AV11+AU11+AT11+AS11+AR11+AQ11+AP11+AO11+AN11+AM11+AL11+AK11+AJ11+AI11+AH11+AG11+AF11+AE11+AD11+AC11+AB11+AA11+Z11+Y11+X11+W11+V11+U11+T11+S11+R11+Q11+P11+O11+N11+M11+L11+K11+J11+I11+H11+G11+F11+E11+D11+C11 -> 0
A12: A1.4425 | B12: PBTPETGF15DSP8T | L12: 300 | BN12: =BM12+BL12+BK12+BJ12+BI12+BH12+BG12+BF12+BE12+BD12+BC12+BB12+BA12+AZ12+AY12+AX12+AW12+AV12+AU12+AT12+AS12+AR12+AQ12+AP12+AO12+AN12+AM12+AL12+AK12+AJ12+AI12+AH12+AG12+AF12+AE12+AD12+AC12+AB12+AA12+Z12+Y12+X12+W12+V12+U12+T12+S12+R12+Q12+P12+O12+N12+M12+L12+K12+J12+I12+H12+G12+F12+E12+D12+C12 -> 300
A13: A1.5108 | B13: POM3807 | BN13: =BM13+BL13+BK13+BJ13+BI13+BH13+BG13+BF13+BE13+BD13+BC13+BB13+BA13+AZ13+AY13+AX13+AW13+AV13+AU13+AT13+AS13+AR13+AQ13+AP13+AO13+AN13+AM13+AL13+AK13+AJ13+AI13+AH13+AG13+AF13+AE13+AD13+AC13+AB13+AA13+Z13+Y13+X13+W13+V13+U13+T13+S13+R13+Q13+P13+O13+N13+M13+L13+K13+J13+I13+H13+G13+F13+E13+D13+C13 -> 0
A14: A1.5109 | B14: POM 588P | J14: 190 | BN14: =BM14+BL14+BK14+BJ14+BI14+BH14+BG14+BF14+BE14+BD14+BC14+BB14+BA14+AZ14+AY14+AX14+AW14+AV14+AU14+AT14+AS14+AR14+AQ14+AP14+AO14+AN14+AM14+AL14+AK14+AJ14+AI14+AH14+AG14+AF14+AE14+AD14+AC14+AB14+AA14+Z14+Y14+X14+W14+V14+U14+T14+S14+R14+Q14+P14+O14+N14+M14+L14+K14+J14+I14+H14+G14+F14+E14+D14+C14 -> 190
A15: A1.5227 | B15: TPO CPREPND TD20 | F15: 1000 | BN15: =BM15+BL15+BK15+BJ15+BI15+BH15+BG15+BF15+BE15+BD15+BC15+BB15+BA15+AZ15+AY15+AX15+AW15+AV15+AU15+AT15+AS15+AR15+AQ15+AP15+AO15+AN15+AM15+AL15+AK15+AJ15+AI15+AH15+AG15+AF15+AE15+AD15+AC15+AB15+AA15+Z15+Y15+X15+W15+V15+U15+T15+S15+R15+Q15+P15+O15+N15+M15+L15+K15+J15+I15+H15+G15+F15+E15+D15+C15 -> 1000
A16: A1.5230 | B16: PPC3122F-M117 | H16: 500 | BN16: =BM16+BL16+BK16+BJ16+BI16+BH16+BG16+BF16+BE16+BD16+BC16+BB16+BA16+AZ16+AY16+AX16+AW16+AV16+AU16+AT16+AS16+AR16+AQ16+AP16+AO16+AN16+AM16+AL16+AK16+AJ16+AI16+AH16+AG16+AF16+AE16+AD16+AC16+AB16+AA16+Z16+Y16+X16+W16+V16+U16+T16+S16+R16+Q16+P16+O16+N16+M16+L16+K16+J16+I16+H16+G16+F16+E16+D16+C16 -> 500
A17: A1.5231 | B17: PPC3322T | BN17: =BM17+BL17+BK17+BJ17+BI17+BH17+BG17+BF17+BE17+BD17+BC17+BB17+BA17+AZ17+AY17+AX17+AW17+AV17+AU17+AT17+AS17+AR17+AQ17+AP17+AO17+AN17+AM17+AL17+AK17+AJ17+AI17+AH17+AG17+AF17+AE17+AD17+AC17+AB17+AA17+Z17+Y17+X17+W17+V17+U17+T17+S17+R17+Q17+P17+O17+N17+M17+L17+K17+J17+I17+H17+G17+F17+E17+D17+C17 -> 0
A18: A1.5232 | B18: PPC3322T -M125(JM8) | G18: 1000 | BN18: =BM18+BL18+BK18+BJ18+BI18+BH18+BG18+BF18+BE18+BD18+BC18+BB18+BA18+AZ18+AY18+AX18+AW18+AV18+AU18+AT18+AS18+AR18+AQ18+AP18+AO18+AN18+AM18+AL18+AK18+AJ18+AI18+AH18+AG18+AF18+AE18+AD18+AC18+AB18+AA18+Z18+Y18+X18+W18+V18+U18+T18+S18+R18+Q18+P18+O18+N18+M18+L18+K18+J18+I18+H18+G18+F18+E18+D18+C18 -> 1000
A19: A1.5260 | B19: PP +EPDM+T20EG299 | BN19: =BM19+BL19+BK19+BJ19+BI19+BH19+BG19+BF19+BE19+BD19+BC19+BB19+BA19+AZ19+AY19+AX19+AW19+AV19+AU19+AT19+AS19+AR19+AQ19+AP19+AO19+AN19+AM19+AL19+AK19+AJ19+AI19+AH19+AG19+AF19+AE19+AD19+AC19+AB19+AA19+Z19+Y19+X19+W19+V19+U19+T19+S19+R19+Q19+P19+O19+N19+M19+L19+K19+J19+I19+H19+G19+F19+E19+D19+C19 -> 0
A20: A1.5264 | B20: PPERC161NCN15926 | BN20: =BM20+BL20+BK20+BJ20+BI20+BH20+BG20+BF20+BE20+BD20+BC20+BB20+BA20+AZ20+AY20+AX20+AW20+AV20+AU20+AT20+AS20+AR20+AQ20+AP20+AO20+AN20+AM20+AL20+AK20+AJ20+AI20+AH20+AG20+AF20+AE20+AD20+AC20+AB20+AA20+Z20+Y20+X20+W20+V20+U20+T20+S20+R20+Q20+P20+O20+N20+M20+L20+K20+J20+I20+H20+G20+F20+E20+D20+C20 -> 0
A21: A1.5313 | B21: PPGF30 HSBK011 | L21: 1000 | BN21: =BM21+BL21+BK21+BJ21+BI21+BH21+BG21+BF21+BE21+BD21+BC21+BB21+BA21+AZ21+AY21+AX21+AW21+AV21+AU21+AT21+AS21+AR21+AQ21+AP21+AO21+AN21+AM21+AL21+AK21+AJ21+AI21+AH21+AG21+AF21+AE21+AD21+AC21+AB21+AA21+Z21+Y21+X21+W21+V21+U21+T21+S21+R21+Q21+P21+O21+N21+M21+L21+K21+J21+I21+H21+G21+F21+E21+D21+C21 -> 1000
A22: A1.5157 | B22: POM M9044 | BN22: =BM22+BL22+BK22+BJ22+BI22+BH22+BG22+BF22+BE22+BD22+BC22+BB22+BA22+AZ22+AY22+AX22+AW22+AV22+AU22+AT22+AS22+AR22+AQ22+AP22+AO22+AN22+AM22+AL22+AK22+AJ22+AI22+AH22+AG22+AF22+AE22+AD22+AC22+AB22+AA22+Z22+Y22+X22+W22+V22+U22+T22+S22+R22+Q22+P22+O22+N22+M22+L22+K22+J22+I22+H22+G22+F22+E22+D22+C22 -> 0
A23: A1.5193 | B23: PP A422 GM304C | BN23: =BM23+BL23+BK23+BJ23+BI23+BH23+BG23+BF23+BE23+BD23+BC23+BB23+BA23+AZ23+AY23+AX23+AW23+AV23+AU23+AT23+AS23+AR23+AQ23+AP23+AO23+AN23+AM23+AL23+AK23+AJ23+AI23+AH23+AG23+AF23+AE23+AD23+AC23+AB23+AA23+Z23+Y23+X23+W23+V23+U23+T23+S23+R23+Q23+P23+O23+N23+M23+L23+K23+J23+I23+H23+G23+F23+E23+D23+C23 -> 0
A24: A1.5195 | B24: PP A422L630 | D24: 1000 | BN24: =BM24+BL24+BK24+BJ24+BI24+BH24+BG24+BF24+BE24+BD24+BC24+BB24+BA24+AZ24+AY24+AX24+AW24+AV24+AU24+AT24+AS24+AR24+AQ24+AP24+AO24+AN24+AM24+AL24+AK24+AJ24+AI24+AH24+AG24+AF24+AE24+AD24+AC24+AB24+AA24+Z24+Y24+X24+W24+V24+U24+T24+S24+R24+Q24+P24+O24+N24+M24+L24+K24+J24+I24+H24+G24+F24+E24+D24+C24 -> 1000
A25: A1.5228 | B25: PP C332EF M12FCB | BN25: =BM25+BL25+BK25+BJ25+BI25+BH25+BG25+BF25+BE25+BD25+BC25+BB25+BA25+AZ25+AY25+AX25+AW25+AV25+AU25+AT25+AS25+AR25+AQ25+AP25+AO25+AN25+AM25+AL25+AK25+AJ25+AI25+AH25+AG25+AF25+AE25+AD25+AC25+AB25+AA25+Z25+Y25+X25+W25+V25+U25+T25+S25+R25+Q25+P25+O25+N25+M25+L25+K25+J25+I25+H25+G25+F25+E25+D25+C25 -> 0
A26: A1.5233 | B26: PP C33207 M12F | BN26: =BM26+BL26+BK26+BJ26+BI26+BH26+BG26+BF26+BE26+BD26+BC26+BB26+BA26+AZ26+AY26+AX26+AW26+AV26+AU26+AT26+AS26+AR26+AQ26+AP26+AO26+AN26+AM26+AL26+AK26+AJ26+AI26+AH26+AG26+AF26+AE26+AD26+AC26+AB26+AA26+Z26+Y26+X26+W26+V26+U26+T26+S26+R26+Q26+P26+O26+N26+M26+L26+K26+J26+I26+H26+G26+F26+E26+D26+C26 -> 0
A27: A1.5236 | B27: PP C654OL-638B | M27: 1000 | BN27: =BM27+BL27+BK27+BJ27+BI27+BH27+BG27+BF27+BE27+BD27+BC27+BB27+BA27+AZ27+AY27+AX27+AW27+AV27+AU27+AT27+AS27+AR27+AQ27+AP27+AO27+AN27+AM27+AL27+AK27+AJ27+AI27+AH27+AG27+AF27+AE27+AD27+AC27+AB27+AA27+Z27+Y27+X27+W27+V27+U27+T27+S27+R27+Q27+P27+O27+N27+M27+L27+K27+J27+I27+H27+G27+F27+E27+D27+C27 -> 1000
A28: A1.5326 | B28: PP H1407R | BN28: =BM28+BL28+BK28+BJ28+BI28+BH28+BG28+BF28+BE28+BD28+BC28+BB28+BA28+AZ28+AY28+AX28+AW28+AV28+AU28+AT28+AS28+AR28+AQ28+AP28+AO28+AN28+AM28+AL28+AK28+AJ28+AI28+AH28+AG28+AF28+AE28+AD28+AC28+AB28+AA28+Z28+Y28+X28+W28+V28+U28+T28+S28+R28+Q28+P28+O28+N28+M28+L28+K28+J28+I28+H28+G28+F28+E28+D28+C28 -> 0
A29: A1.5328 | B29: PP11FX TYC1152PBK | BN29: =BM29+BL29+BK29+BJ29+BI29+BH29+BG29+BF29+BE29+BD29+BC29+BB29+BA29+AZ29+AY29+AX29+AW29+AV29+AU29+AT29+AS29+AR29+AQ29+AP29+AO29+AN29+AM29+AL29+AK29+AJ29+AI29+AH29+AG29+AF29+AE29+AD29+AC29+AB29+AA29+Z29+Y29+X29+W29+V29+U29+T29+S29+R29+Q29+P29+O29+N29+M29+L29+K29+J29+I29+H29+G29+F29+E29+D29+C29 -> 0
A30: A1.5345 | B30: PP MD20 ECO | BN30: =BM30+BL30+BK30+BJ30+BI30+BH30+BG30+BF30+BE30+BD30+BC30+BB30+BA30+AZ30+AY30+AX30+AW30+AV30+AU30+AT30+AS30+AR30+AQ30+AP30+AO30+AN30+AM30+AL30+AK30+AJ30+AI30+AH30+AG30+AF30+AE30+AD30+AC30+AB30+AA30+Z30+Y30+X30+W30+V30+U30+T30+S30+R30+Q30+P30+O30+N30+M30+L30+K30+J30+I30+H30+G30+F30+E30+D30+C30 -> 0
A31: A1.5357 | H31: 500 | BN31: =BM31+BL31+BK31+BJ31+BI31+BH31+BG31+BF31+BE31+BD31+BC31+BB31+BA31+AZ31+AY31+AX31+AW31+AV31+AU31+AT31+AS31+AR31+AQ31+AP31+AO31+AN31+AM31+AL31+AK31+AJ31+AI31+AH31+AG31+AF31+AE31+AD31+AC31+AB31+AA31+Z31+Y31+X31+W31+V31+U31+T31+S31+R31+Q31+P31+O31+N31+M31+L31+K31+J31+I31+H31+G31+F31+E31+D31+C31 -> 500
A32: A1.5358 | B32: PP-T20A5132T(JM8) | H32: 1000 | BN32: =BM32+BL32+BK32+BJ32+BI32+BH32+BG32+BF32+BE32+BD32+BC32+BB32+BA32+AZ32+AY32+AX32+AW32+AV32+AU32+AT32+AS32+AR32+AQ32+AP32+AO32+AN32+AM32+AL32+AK32+AJ32+AI32+AH32+AG32+AF32+AE32+AD32+AC32+AB32+AA32+Z32+Y32+X32+W32+V32+U32+T32+S32+R32+Q32+P32+O32+N32+M32+L32+K32+J32+I32+H32+G32+F32+E32+D32+C32 -> 1000
A33: A1.5380 | B33: PP TD17 BMV214W | F33: 1000 | BN33: =BM33+BL33+BK33+BJ33+BI33+BH33+BG33+BF33+BE33+BD33+BC33+BB33+BA33+AZ33+AY33+AX33+AW33+AV33+AU33+AT33+AS33+AR33+AQ33+AP33+AO33+AN33+AM33+AL33+AK33+AJ33+AI33+AH33+AG33+AF33+AE33+AD33+AC33+AB33+AA33+Z33+Y33+X33+W33+V33+U33+T33+S33+R33+Q33+P33+O33+N33+M33+L33+K33+J33+I33+H33+G33+F33+E33+D33+C33 -> 1000
A34: A1.5386 | B34: PPTYC 852P | BN34: =BM34+BL34+BK34+BJ34+BI34+BH34+BG34+BF34+BE34+BD34+BC34+BB34+BA34+AZ34+AY34+AX34+AW34+AV34+AU34+AT34+AS34+AR34+AQ34+AP34+AO34+AN34+AM34+AL34+AK34+AJ34+AI34+AH34+AG34+AF34+AE34+AD34+AC34+AB34+AA34+Z34+Y34+X34+W34+V34+U34+T34+S34+R34+Q34+P34+O34+N34+M34+L34+K34+J34+I34+H34+G34+F34+E34+D34+C34 -> 0
A35: A1.5388 | B35: PP/EPD121 | BN35: =BM35+BL35+BK35+BJ35+BI35+BH35+BG35+BF35+BE35+BD35+BC35+BB35+BA35+AZ35+AY35+AX35+AW35+AV35+AU35+AT35+AS35+AR35+AQ35+AP35+AO35+AN35+AM35+AL35+AK35+AJ35+AI35+AH35+AG35+AF35+AE35+AD35+AC35+AB35+AA35+Z35+Y35+X35+W35+V35+U35+T35+S35+R35+Q35+P35+O35+N35+M35+L35+K35+J35+I35+H35+G35+F35+E35+D35+C35 -> 0
A36: A1.5420 | B36: PP+EPPM+T20 | BN36: =BM36+BL36+BK36+BJ36+BI36+BH36+BG36+BF36+BE36+BD36+BC36+BB36+BA36+AZ36+AY36+AX36+AW36+AV36+AU36+AT36+AS36+AR36+AQ36+AP36+AO36+AN36+AM36+AL36+AK36+AJ36+AI36+AH36+AG36+AF36+AE36+AD36+AC36+AB36+AA36+Z36+Y36+X36+W36+V36+U36+T36+S36+R36+Q36+P36+O36+N36+M36+L36+K36+J36+I36+H36+G36+F36+E36+D36+C36 -> 0
A37: A1.5422 | B37: PP+EPPM+TD20 | BN37: =BM37+BL37+BK37+BJ37+BI37+BH37+BG37+BF37+BE37+BD37+BC37+BB37+BA37+AZ37+AY37+AX37+AW37+AV37+AU37+AT37+AS37+AR37+AQ37+AP37+AO37+AN37+AM37+AL37+AK37+AJ37+AI37+AH37+AG37+AF37+AE37+AD37+AC37+AB37+AA37+Z37+Y37+X37+W37+V37+U37+T37+S37+R37+Q37+P37+O37+N37+M37+L37+K37+J37+I37+H37+G37+F37+E37+D37+C37 -> 0
A38: A1.4166 | B38: ABS HH106 | BN38: =BM38+BL38+BK38+BJ38+BI38+BH38+BG38+BF38+BE38+BD38+BC38+BB38+BA38+AZ38+AY38+AX38+AW38+AV38+AU38+AT38+AS38+AR38+AQ38+AP38+AO38+AN38+AM38+AL38+AK38+AJ38+AI38+AH38+AG38+AF38+AE38+AD38+AC38+AB38+AA38+Z38+Y38+X38+W38+V38+U38+T38+S38+R38+Q38+P38+O38+N38+M38+L38+K38+J38+I38+H38+G38+F38+E38+D38+C38 -> 0
A39: A1.5413 | B39: PP+EPDM+HTTD020 | L39: 1000 | BN39: =BM39+BL39+BK39+BJ39+BI39+BH39+BG39+BF39+BE39+BD39+BC39+BB39+BA39+AZ39+AY39+AX39+AW39+AV39+AU39+AT39+AS39+AR39+AQ39+AP39+AO39+AN39+AM39+AL39+AK39+AJ39+AI39+AH39+AG39+AF39+AE39+AD39+AC39+AB39+AA39+Z39+Y39+X39+W39+V39+U39+T39+S39+R39+Q39+P39+O39+N39+M39+L39+K39+J39+I39+H39+G39+F39+E39+D39+C39 -> 1000
A40: A1.5493 | B40: TEO-3000-60A黑 | BN40: =BM40+BL40+BK40+BJ40+BI40+BH40+BG40+BF40+BE40+BD40+BC40+BB40+BA40+AZ40+AY40+AX40+AW40+AV40+AU40+AT40+AS40+AR40+AQ40+AP40+AO40+AN40+AM40+AL40+AK40+AJ40+AI40+AH40+AG40+AF40+AE40+AD40+AC40+AB40+AA40+Z40+Y40+X40+W40+V40+U40+T40+S40+R40+Q40+P40+O40+N40+M40+L40+K40+J40+I40+H40+G40+F40+E40+D40+C40 -> 0
...

Sheet 2023年9月材料领用             
A1: 2023年9月份深远材料辅件领用清单
A2: 材料代码 | B2: 日期 数量 名称 | C2: 45173 | D2: 45175 | E2: 45176 | F2: 45179 | G2: 45180 | H2: 45181 | I2: 45182 | J2: 45183 | K2: 45187 | L2: 45189 | M2: 45193 | N2: 45194 | BM2: 45195 | BN2: 深远 | BO2: 杭友
A3: A1.1811 | B3: PP-CGF+TD235 | BN3: =BM3+BL3+BK3+BJ3+BI3+BH3+BG3+BF3+BE3+BD3+BC3+BB3+BA3+AZ3+AY3+AX3+AW3+AV3+AU3+AT3+AS3+AR3+AQ3+AP3+AO3+AN3+AM3+AL3+AK3+AJ3+AI3+AH3+AG3+AF3+AE3+AD3+AC3+AB3+AA3+Z3+Y3+X3+W3+V3+U3+T3+S3+R3+Q3+P3+O3+N3+M3+L3+K3+J3+I3+H3+G3+F3+E3+D3+C3 -> 0
A4: A1.1812 | B4: PA6 BKV60HZ.0WSS | BN4: =BM4+BL4+BK4+BJ4+BI4+BH4+BG4+BF4+BE4+BD4+BC4+BB4+BA4+AZ4+AY4+AX4+AW4+AV4+AU4+AT4+AS4+AR4+AQ4+AP4+AO4+AN4+AM4+AL4+AK4+AJ4+AI4+AH4+AG4+AF4+AE4+AD4+AC4+AB4+AA4+Z4+Y4+X4+W4+V4+U4+T4+S4+R4+Q4+P4+O4+N4+M4+L4+K4+J4+I4+H4+G4+F4+E4+D4+C4 -> 0
A5: A1.1131 | B5: PA66-FG30A104GH | BN5: =BM5+BL5+BK5+BJ5+BI5+BH5+BG5+BF5+BE5+BD5+BC5+BB5+BA5+AZ5+AY5+AX5+AW5+AV5+AU5+AT5+AS5+AR5+AQ5+AP5+AO5+AN5+AM5+AL5+AK5+AJ5+AI5+AH5+AG5+AF5+AE5+AD5+AC5+AB5+AA5+Z5+Y5+X5+W5+V5+U5+T5+S5+R5+Q5+P5+O5+N5+M5+L5+K5+J5+I5+H5+G5+F5+E5+D5+C5 -> 0
A6: A5.4332 | B6: PA66 101LNC010 | BN6: =BM6+BL6+BK6+BJ6+BI6+BH6+BG6+BF6+BE6+BD6+BC6+BB6+BA6+AZ6+AY6+AX6+AW6+AV6+AU6+AT6+AS6+AR6+AQ6+AP6+AO6+AN6+AM6+AL6+AK6+AJ6+AI6+AH6+AG6+AF6+AE6+AD6+AC6+AB6+AA6+Z6+Y6+X6+W6+V6+U6+T6+S6+R6+Q6+P6+O6+N6+M6+L6+K6+J6+I6+H6+G6+F6+E6+D6+C6 -> 0
A7: A1.4335 | B7: PA66 A3K NC | BN7: =BM7+BL7+BK7+BJ7+BI7+BH7+BG7+BF7+BE7+BD7+BC7+BB7+BA7+AZ7+AY7+AX7+AW7+AV7+AU7+AT7+AS7+AR7+AQ7+AP7+AO7+AN7+AM7+AL7+AK7+AJ7+AI7+AH7+AG7+AF7+AE7+AD7+AC7+AB7+AA7+Z7+Y7+X7+W7+V7+U7+T7+S7+R7+Q7+P7+O7+N7+M7+L7+K7+J7+I7+H7+G7+F7+E7+D7+C7 -> 0
A8: A1.4338 | B8: PA66 C200 BK121 | BM8: 2000 | BN8: =BM8+BL8+BK8+BJ8+BI8+BH8+BG8+BF8+BE8+BD8+BC8+BB8+BA8+AZ8+AY8+AX8+AW8+AV8+AU8+AT8+AS8+AR8+AQ8+AP8+AO8+AN8+AM8+AL8+AK8+AJ8+AI8+AH8+AG8+AF8+AE8+AD8+AC8+AB8+AA8+Z8+Y8+X8+W8+V8+U8+T8+S8+R8+Q8+P8+O8+N8+M8+L8+K8+J8+I8+H8+G8+F8+E8+D8+C8 -> 2000
A9: A1.4354 | B9: PA66GF30AKROM117 | BN9: =BM9+BL9+BK9+BJ9+BI9+BH9+BG9+BF9+BE9+BD9+BC9+BB9+BA9+AZ9+AY9+AX9+AW9+AV9+AU9+AT9+AS9+AR9+AQ9+AP9+AO9+AN9+AM9+AL9+AK9+AJ9+AI9+AH9+AG9+AF9+AE9+AD9+AC9+AB9+AA9+Z9+Y9+X9+W9+V9+U9+T9+S9+R9+Q9+P9+O9+N9+M9+L9+K9+J9+I9+H9+G9+F9+E9+D9+C9 -> 0
A10: A1.4377 | B10: PA6 ALCOM GF10 | L10: 1600 | BM10: 1600 | BN10: =BM10+BL10+BK10+BJ10+BI10+BH10+BG10+BF10+BE10+BD10+BC10+BB10+BA10+AZ10+AY10+AX10+AW10+AV10+AU10+AT10+AS10+AR10+AQ10+AP10+AO10+AN10+AM10+AL10+AK10+AJ10+AI10+AH10+AG10+AF10+AE10+AD10+AC10+AB10+AA10+Z10+Y10+X10+W10+V10+U10+T10+S10+R10+Q10+P10+O10+N10+M10+L10+K10+J10+I10+H10+G10+F10+E10+D10+C10 -> 3200
A11: A1.4404 | B11: PBTGFH | BN11: =BM11+BL11+BK11+BJ11+BI11+BH11+BG11+BF11+BE11+BD11+BC11+BB11+BA11+AZ11+AY11+AX11+AW11+AV11+AU11+AT11+AS11+AR11+AQ11+AP11+AO11+AN11+AM11+AL11+AK11+AJ11+AI11+AH11+AG11+AF11+AE11+AD11+AC11+AB11+AA11+Z11+Y11+X11+W11+V11+U11+T11+S11+R11+Q11+P11+O11+N11+M11+L11+K11+J11+I11+H11+G11+F11+E11+D11+C11 -> 0
A12: A1.4425 | B12: PBTPETGF15DSP8T | N12: 200 | BN12: =BM12+BL12+BK12+BJ12+BI12+BH12+BG12+BF12+BE12+BD12+BC12+BB12+BA12+AZ12+AY12+AX12+AW12+AV12+AU12+AT12+AS12+AR12+AQ12+AP12+AO12+AN12+AM12+AL12+AK12+AJ12+AI12+AH12+AG12+AF12+AE12+AD12+AC12+AB12+AA12+Z12+Y12+X12+W12+V12+U12+T12+S12+R12+Q12+P12+O12+N12+M12+L12+K12+J12+I12+H12+G12+F12+E12+D12+C12 -> 200
A13: A1.5108 | B13: POM3807 | BN13: =BM13+BL13+BK13+BJ13+BI13+BH13+BG13+BF13+BE13+BD13+BC13+BB13+BA13+AZ13+AY13+AX13+AW13+AV13+AU13+AT13+AS13+AR13+AQ13+AP13+AO13+AN13+AM13+AL13+AK13+AJ13+AI13+AH13+AG13+AF13+AE13+AD13+AC13+AB13+AA13+Z13+Y13+X13+W13+V13+U13+T13+S13+R13+Q13+P13+O13+N13+M13+L13+K13+J13+I13+H13+G13+F13+E13+D13+C13 -> 0
A14: A1.5227 | B14: TPO CPREPND TD20 | BN14: =BM14+BL14+BK14+BJ14+BI14+BH14+BG14+BF14+BE14+BD14+BC14+BB14+BA14+AZ14+AY14+AX14+AW14+AV14+AU14+AT14+AS14+AR14+AQ14+AP14+AO14+AN14+AM14+AL14+AK14+AJ14+AI14+AH14+AG14+AF14+AE14+AD14+AC14+AB14+AA14+Z14+Y14+X14+W14+V14+U14+T14+S14+R14+Q14+P14+O14+N14+M14+L14+K14+J14+I14+H14+G14+F14+E14+D14+C14 -> 0
A15: A1.5230 | B15: PPC3122F-M117 | G15: 400 | BN15: =BM15+BL15+BK15+BJ15+BI15+BH15+BG15+BF15+BE15+BD15+BC15+BB15+BA15+AZ15+AY15+AX15+AW15+AV15+AU15+AT15+AS15+AR15+AQ15+AP15+AO15+AN15+AM15+AL15+AK15+AJ15+AI15+AH15+AG15+AF15+AE15+AD15+AC15+AB15+AA15+Z15+Y15+X15+W15+V15+U15+T15+S15+R15+Q15+P15+O15+N15+M15+L15+K15+J15+I15+H15+G15+F15+E15+D15+C15 -> 400
A16: A1.5231 | B16: PPC3322T | BN16: =BM16+BL16+BK16+BJ16+BI16+BH16+BG16+BF16+BE16+BD16+BC16+BB16+BA16+AZ16+AY16+AX16+AW16+AV16+AU16+AT16+AS16+AR16+AQ16+AP16+AO16+AN16+AM16+AL16+AK16+AJ16+AI16+AH16+AG16+AF16+AE16+AD16+AC16+AB16+AA16+Z16+Y16+X16+W16+V16+U16+T16+S16+R16+Q16+P16+O16+N16+M16+L16+K16+J16+I16+H16+G16+F16+E16+D16+C16 -> 0
A17: A1.5232 | B17: PPC3322T -M125(JM8) | I17: 1000 | M17: 1000 | BM17: -300 | BN17: =BM17+BL17+BK17+BJ17+BI17+BH17+BG17+BF17+BE17+BD17+BC17+BB17+BA17+AZ17+AY17+AX17+AW17+AV17+AU17+AT17+AS17+AR17+AQ17+AP17+AO17+AN17+AM17+AL17+AK17+AJ17+AI17+AH17+AG17+AF17+AE17+AD17+AC17+AB17+AA17+Z17+Y17+X17+W17+V17+U17+T17+S17+R17+Q17+P17+O17+N17+M17+L17+K17+J17+I17+H17+G17+F17+E17+D17+C17 -> 1700
A18: A1.5260 | B18: PP +EPDM+T20EG299 | BN18: =BM18+BL18+BK18+BJ18+BI18+BH18+BG18+BF18+BE18+BD18+BC18+BB18+BA18+AZ18+AY18+AX18+AW18+AV18+AU18+AT18+AS18+AR18+AQ18+AP18+AO18+AN18+AM18+AL18+AK18+AJ18+AI18+AH18+AG18+AF18+AE18+AD18+AC18+AB18+AA18+Z18+Y18+X18+W18+V18+U18+T18+S18+R18+Q18+P18+O18+N18+M18+L18+K18+J18+I18+H18+G18+F18+E18+D18+C18 -> 0
A19: A1.5264 | B19: PPERC161NCN15926 | BN19: =BM19+BL19+BK19+BJ19+BI19+BH19+BG19+BF19+BE19+BD19+BC19+BB19+BA19+AZ19+AY19+AX19+AW19+AV19+AU19+AT19+AS19+AR19+AQ19+AP19+AO19+AN19+AM19+AL19+AK19+AJ19+AI19+AH19+AG19+AF19+AE19+AD19+AC19+AB19+AA19+Z19+Y19+X19+W19+V19+U19+T19+S19+R19+Q19+P19+O19+N19+M19+L19+K19+J19+I19+H19+G19+F19+E19+D19+C19 -> 0
A20: A1.5313 | B20: PPGF30 HSBK011 | F20: 1000 | N20: 500 | BN20: =BM20+BL20+BK20+BJ20+BI20+BH20+BG20+BF20+BE20+BD20+BC20+BB20+BA20+AZ20+AY20+AX20+AW20+AV20+AU20+AT20+AS20+AR20+AQ20+AP20+AO20+AN20+AM20+AL20+AK20+AJ20+AI20+AH20+AG20+AF20+AE20+AD20+AC20+AB20+AA20+Z20+Y20+X20+W20+V20+U20+T20+S20+R20+Q20+P20+O20+N20+M20+L20+K20+J20+I20+H20+G20+F20+E20+D20+C20 -> 1500
A21: A1.5157 | B21: POM M9044 | BN21: =BM21+BL21+BK21+BJ21+BI21+BH21+BG21+BF21+BE21+BD21+BC21+BB21+BA21+AZ21+AY21+AX21+AW21+AV21+AU21+AT21+AS21+AR21+AQ21+AP21+AO21+AN21+AM21+AL21+AK21+AJ21+AI21+AH21+AG21+AF21+AE21+AD21+AC21+AB21+AA21+Z21+Y21+X21+W21+V21+U21+T21+S21+R21+Q21+P21+O21+N21+M21+L21+K21+J21+I21+H21+G21+F21+E21+D21+C21 -> 0
A22: A1.5193 | B22: PP A422 GM304C | BN22: =BM22+BL22+BK22+BJ22+BI22+BH22+BG22+BF22+BE22+BD22+BC22+BB22+BA22+AZ22+AY22+AX22+AW22+AV22+AU22+AT22+AS22+AR22+AQ22+AP22+AO22+AN22+AM22+AL22+AK22+AJ22+AI22+AH22+AG22+AF22+AE22+AD22+AC22+AB22+AA22+Z22+Y22+X22+W22+V22+U22+T22+S22+R22+Q22+P22+O22+N22+M22+L22+K22+J22+I22+H22+G22+F22+E22+D22+C22 -> 0
A23: A1.5195 | B23: PP A422L630 | C23: 1550 | BN23: =BM23+BL23+BK23+BJ23+BI23+BH23+BG23+BF23+BE23+BD23+BC23+BB23+BA23+AZ23+AY23+AX23+AW23+AV23+AU23+AT23+AS23+AR23+AQ23+AP23+AO23+AN23+AM23+AL23+AK23+AJ23+AI23+AH23+AG23+AF23+AE23+AD23+AC23+AB23+AA23+Z23+Y23+X23+W23+V23+U23+T23+S23+R23+Q23+P23+O23+N23+M23+L23+K23+J23+I23+H23+G23+F23+E23+D23+C23 -> 1550
A24: A1.5228 | B24: PP C332EF M12FCB | BN24: =BM24+BL24+BK24+BJ24+BI24+BH24+BG24+BF24+BE24+BD24+BC24+BB24+BA24+AZ24+AY24+AX24+AW24+AV24+AU24+AT24+AS24+AR24+AQ24+AP24+AO24+AN24+AM24+AL24+AK24+AJ24+AI24+AH24+AG24+AF24+AE24+AD24+AC24+AB24+AA24+Z24+Y24+X24+W24+V24+U24+T24+S24+R24+Q24+P24+O24+N24+M24+L24+K24+J24+I24+H24+G24+F24+E24+D24+C24 -> 0
A25: A1.5233 | B25: PP C33207 M12F | BN25: =BM25+BL25+BK25+BJ25+BI25+BH25+BG25+BF25+BE25+BD25+BC25+BB25+BA25+AZ25+AY25+AX25+AW25+AV25+AU25+AT25+AS25+AR25+AQ25+AP25+AO25+AN25+AM25+AL25+AK25+AJ25+AI25+AH25+AG25+AF25+AE25+AD25+AC25+AB25+AA25+Z25+Y25+X25+W25+V25+U25+T25+S25+R25+Q25+P25+O25+N25+M25+L25+K25+J25+I25+H25+G25+F25+E25+D25+C25 -> 0
A26: A1.5236 | B26: PP C654OL-638B | E26: 125 | J26: 300 | N26: 1200 | BN26: =BM26+BL26+BK26+BJ26+BI26+BH26+BG26+BF26+BE26+BD26+BC26+BB26+BA26+AZ26+AY26+AX26+AW26+AV26+AU26+AT26+AS26+AR26+AQ26+AP26+AO26+AN26+AM26+AL26+AK26+AJ26+AI26+AH26+AG26+AF26+AE26+AD26+AC26+AB26+AA26+Z26+Y26+X26+W26+V26+U26+T26+S26+R26+Q26+P26+O26+N26+M26+L26+K26+J26+I26+H26+G26+F26+E26+D26+C26 -> 1625
A27: A1.5326 | B27: PP H1407R | M27: 500 | BN27: =BM27+BL27+BK27+BJ27+BI27+BH27+BG27+BF27+BE27+BD27+BC27+BB27+BA27+AZ27+AY27+AX27+AW27+AV27+AU27+AT27+AS27+AR27+AQ27+AP27+AO27+AN27+AM27+AL27+AK27+AJ27+AI27+AH27+AG27+AF27+AE27+AD27+AC27+AB27+AA27+Z27+Y27+X27+W27+V27+U27+T27+S27+R27+Q27+P27+O27+N27+M27+L27+K27+J27+I27+H27+G27+F27+E27+D27+C27 -> 500
A28: A1.5328 | B28: PP11FX TYC1152PBK | BN28: =BM28+BL28+BK28+BJ28+BI28+BH28+BG28+BF28+BE28+BD28+BC28+BB28+BA28+AZ28+AY28+AX28+AW28+AV28+AU28+AT28+AS28+AR28+AQ28+AP28+AO28+AN28+AM28+AL28+AK28+AJ28+AI28+AH28+AG28+AF28+AE28+AD28+AC28+AB28+AA28+Z28+Y28+X28+W28+V28+U28+T28+S28+R28+Q28+P28+O28+N28+M28+L28+K28+J28+I28+H28+G28+F28+E28+D28+C28 -> 0
A29: A1.5345 | B29: PP MD20 ECO | BN29: =BM29+BL29+BK29+BJ29+BI29+BH29+BG29+BF29+BE29+BD29+BC29+BB29+BA29+AZ29+AY29+AX29+AW29+AV29+AU29+AT29+AS29+AR29+AQ29+AP29+AO29+AN29+AM29+AL29+AK29+AJ29+AI29+AH29+AG29+AF29+AE29+AD29+AC29+AB29+AA29+Z29+Y29+X29+W29+V29+U29+T29+S29+R29+Q29+P29+O29+N29+M29+L29+K29+J29+I29+H29+G29+F29+E29+D29+C29 -> 0
A30: A1.5357 | BN30: =BM30+BL30+BK30+BJ30+BI30+BH30+BG30+BF30+BE30+BD30+BC30+BB30+BA30+AZ30+AY30+AX30+AW30+AV30+AU30+AT30+AS30+AR30+AQ30+AP30+AO30+AN30+AM30+AL30+AK30+AJ30+AI30+AH30+AG30+AF30+AE30+AD30+AC30+AB30+AA30+Z30+Y30+X30+W30+V30+U30+T30+S30+R30+Q30+P30+O30+N30+M30+L30+K30+J30+I30+H30+G30+F30+E30+D30+C30 -> 0
A31: A1.5358 | B31: PP-T20A5132T(JM8) | F31: 1000 | M31: 1000 | BN31: =BM31+BL31+BK31+BJ31+BI31+BH31+BG31+BF31+BE31+BD31+BC31+BB31+BA31+AZ31+AY31+AX31+AW31+AV31+AU31+AT31+AS31+AR31+AQ31+AP31+AO31+AN31+AM31+AL31+AK31+AJ31+AI31+AH31+AG31+AF31+AE31+AD31+AC31+AB31+AA31+Z31+Y31+X31+W31+V31+U31+T31+S31+R31+Q31+P31+O31+N31+M31+L31+K31+J31+I31+H31+G31+F31+E31+D31+C31 -> 2000
A32: A1.5380 | B32: PP TD17 BMV214W | K32: 1000 | BN32: =BM32+BL32+BK32+BJ32+BI32+BH32+BG32+BF32+BE32+BD32+BC32+BB32+BA32+AZ32+AY32+AX32+AW32+AV32+AU32+AT32+AS32+AR32+AQ32+AP32+AO32+AN32+AM32+AL32+AK32+AJ32+AI32+AH32+AG32+AF32+AE32+AD32+AC32+AB32+AA32+Z32+Y32+X32+W32+V32+U32+T32+S32+R32+Q32+P32+O32+N32+M32+L32+K32+J32+I32+H32+G32+F32+E32+D32+C32 -> 1000
A33: A1.5386 | B33: PPTYC 852P | BN33: =BM33+BL33+BK33+BJ33+BI33+BH33+BG33+BF33+BE33+BD33+BC33+BB33+BA33+AZ33+AY33+AX33+AW33+AV33+AU33+AT33+AS33+AR33+AQ33+AP33+AO33+AN33+AM33+AL33+AK33+AJ33+AI33+AH33+AG33+AF33+AE33+AD33+AC33+AB33+AA33+Z33+Y33+X33+W33+V33+U33+T33+S33+R33+Q33+P33+O33+N33+M33+L33+K33+J33+I33+H33+G33+F33+E33+D33+C33 -> 0
A34: A1.5388 | B34: PP/EPD121 | BN34: =BM34+BL34+BK34+BJ34+BI34+BH34+BG34+BF34+BE34+BD34+BC34+BB34+BA34+AZ34+AY34+AX34+AW34+AV34+AU34+AT34+AS34+AR34+AQ34+AP34+AO34+AN34+AM34+AL34+AK34+AJ34+AI34+AH34+AG34+AF34+AE34+AD34+AC34+AB34+AA34+Z34+Y34+X34+W34+V34+U34+T34+S34+R34+Q34+P34+O34+N34+M34+L34+K34+J34+I34+H34+G34+F34+E34+D34+C34 -> 0
A35: A1.5420 | B35: PP+EPPM+T20 | BN35: =BM35+BL35+BK35+BJ35+BI35+BH35+BG35+BF35+BE35+BD35+BC35+BB35+BA35+AZ35+AY35+AX35+AW35+AV35+AU35+AT35+AS35+AR35+AQ35+AP35+AO35+AN35+AM35+AL35+AK35+AJ35+AI35+AH35+AG35+AF35+AE35+AD35+AC35+AB35+AA35+Z35+Y35+X35+W35+V35+U35+T35+S35+R35+Q35+P35+O35+N35+M35+L35+K35+J35+I35+H35+G35+F35+E35+D35+C35 -> 0
A36: A1.5422 | B36: PP+EPPM+TD20 | BN36: =BM36+BL36+BK36+BJ36+BI36+BH36+BG36+BF36+BE36+BD36+BC36+BB36+BA36+AZ36+AY36+AX36+AW36+AV36+AU36+AT36+AS36+AR36+AQ36+AP36+AO36+AN36+AM36+AL36+AK36+AJ36+AI36+AH36+AG36+AF36+AE36+AD36+AC36+AB36+AA36+Z36+Y36+X36+W36+V36+U36+T36+S36+R36+Q36+P36+O36+N36+M36+L36+K36+J36+I36+H36+G36+F36+E36+D36+C36 -> 0
A37: A1.4166 | B37: ABS HH106 | K37: 160 | BN37: =BM37+BL37+BK37+BJ37+BI37+BH37+BG37+BF37+BE37+BD37+BC37+BB37+BA37+AZ37+AY37+AX37+AW37+AV37+AU37+AT37+AS37+AR37+AQ37+AP37+AO37+AN37+AM37+AL37+AK37+AJ37+AI37+AH37+AG37+AF37+AE37+AD37+AC37+AB37+AA37+Z37+Y37+X37+W37+V37+U37+T37+S37+R37+Q37+P37+O37+N37+M37+L37+K37+J37+I37+H37+G37+F37+E37+D37+C37 -> 160
A38: A1.5413 | B38: PP+EPDM+HTTD020 | I38: 1000 | BM38: 1000 | BN38: =BM38+BL38+BK38+BJ38+BI38+BH38+BG38+BF38+BE38+BD38+BC38+BB38+BA38+AZ38+AY38+AX38+AW38+AV38+AU38+AT38+AS38+AR38+AQ38+AP38+AO38+AN38+AM38+AL38+AK38+AJ38+AI38+AH38+AG38+AF38+AE38+AD38+AC38+AB38+AA38+Z38+Y38+X38+W38+V38+U38+T38+S38+R38+Q38+P38+O38+N38+M38+L38+K38+J38+I38+H38+G38+F38+E38+D38+C38 -> 2000
A39: A1.5493 | B39: TEO-3000-60A黑 | BM39: 100 | BN39: =BM39+BL39+BK39+BJ39+BI39+BH39+BG39+BF39+BE39+BD39+BC39+BB39+BA39+AZ39+AY39+AX39+AW39+AV39+AU39+AT39+AS39+AR39+AQ39+AP39+AO39+AN39+AM39+AL39+AK39+AJ39+AI39+AH39+AG39+AF39+AE39+AD39+AC39+AB39+AA39+Z39+Y39+X39+W39+V39+U39+T39+S39+R39+Q39+P39+O39+N39+M39+L39+K39+J39+I39+H39+G39+F39+E39+D39+C39 -> 100
A40: A1.5511 | B40: TPE AT7210-70 | M40: 500 | BN40: =BM40+BL40+BK40+BJ40+BI40+BH40+BG40+BF40+BE40+BD40+BC40+BB40+BA40+AZ40+AY40+AX40+AW40+AV40+AU40+AT40+AS40+AR40+AQ40+AP40+AO40+AN40+AM40+AL40+AK40+AJ40+AI40+AH40+AG40+AF40+AE40+AD40+AC40+AB40+AA40+Z40+Y40+X40+W40+V40+U40+T40+S40+R40+Q40+P40+O40+N40+M40+L40+K40+J40+I40+H40+G40+F40+E40+D40+C40 -> 500
...

Sheet 2023年8月材料L领用            
A1: 2023年7月份深远材料辅件领用清单
A2: 材料代码 | B2: 日期 数量 名称 | C2: 45141 | D2: 45143 | E2: 45152 | F2: 45153 | G2: 45156 | H2: 45159 | I2: 45161 | J2: 8月25 | K2: 45166 | L2: 8月29 | M2: 45168 | N2: 45169 | BN2: 深远
A3: A1.1811 | B3: PP-CGF+TD235 | BN3: =BM3+BL3+BK3+BJ3+BI3+BH3+BG3+BF3+BE3+BD3+BC3+BB3+BA3+AZ3+AY3+AX3+AW3+AV3+AU3+AT3+AS3+AR3+AQ3+AP3+AO3+AN3+AM3+AL3+AK3+AJ3+AI3+AH3+AG3+AF3+AE3+AD3+AC3+AB3+AA3+Z3+Y3+X3+W3+V3+U3+T3+S3+R3+Q3+P3+O3+N3+M3+L3+K3+J3+I3+H3+G3+F3+E3+D3+C3 -> 0
A4: A1.1812 | B4: PA6 BKV60HZ.0WSS | BN4: =BM4+BL4+BK4+BJ4+BI4+BH4+BG4+BF4+BE4+BD4+BC4+BB4+BA4+AZ4+AY4+AX4+AW4+AV4+AU4+AT4+AS4+AR4+AQ4+AP4+AO4+AN4+AM4+AL4+AK4+AJ4+AI4+AH4+AG4+AF4+AE4+AD4+AC4+AB4+AA4+Z4+Y4+X4+W4+V4+U4+T4+S4+R4+Q4+P4+O4+N4+M4+L4+K4+J4+I4+H4+G4+F4+E4+D4+C4 -> 0
A5: A1.1131 | B5: PA66-FG30A104GH | BN5: =BM5+BL5+BK5+BJ5+BI5+BH5+BG5+BF5+BE5+BD5+BC5+BB5+BA5+AZ5+AY5+AX5+AW5+AV5+AU5+AT5+AS5+AR5+AQ5+AP5+AO5+AN5+AM5+AL5+AK5+AJ5+AI5+AH5+AG5+AF5+AE5+AD5+AC5+AB5+AA5+Z5+Y5+X5+W5+V5+U5+T5+S5+R5+Q5+P5+O5+N5+M5+L5+K5+J5+I5+H5+G5+F5+E5+D5+C5 -> 0
A6: A5.4332 | B6: PA66 101LNC010 | BN6: =BM6+BL6+BK6+BJ6+BI6+BH6+BG6+BF6+BE6+BD6+BC6+BB6+BA6+AZ6+AY6+AX6+AW6+AV6+AU6+AT6+AS6+AR6+AQ6+AP6+AO6+AN6+AM6+AL6+AK6+AJ6+AI6+AH6+AG6+AF6+AE6+AD6+AC6+AB6+AA6+Z6+Y6+X6+W6+V6+U6+T6+S6+R6+Q6+P6+O6+N6+M6+L6+K6+J6+I6+H6+G6+F6+E6+D6+C6 -> 0
A7: A1.4335 | B7: PA66 A3K NC | BN7: =BM7+BL7+BK7+BJ7+BI7+BH7+BG7+BF7+BE7+BD7+BC7+BB7+BA7+AZ7+AY7+AX7+AW7+AV7+AU7+AT7+AS7+AR7+AQ7+AP7+AO7+AN7+AM7+AL7+AK7+AJ7+AI7+AH7+AG7+AF7+AE7+AD7+AC7+AB7+AA7+Z7+Y7+X7+W7+V7+U7+T7+S7+R7+Q7+P7+O7+N7+M7+L7+K7+J7+I7+H7+G7+F7+E7+D7+C7 -> 0
A8: A1.4338 | B8: PA66 C200 BK121 | J8: 1000 | BN8: =BM8+BL8+BK8+BJ8+BI8+BH8+BG8+BF8+BE8+BD8+BC8+BB8+BA8+AZ8+AY8+AX8+AW8+AV8+AU8+AT8+AS8+AR8+AQ8+AP8+AO8+AN8+AM8+AL8+AK8+AJ8+AI8+AH8+AG8+AF8+AE8+AD8+AC8+AB8+AA8+Z8+Y8+X8+W8+V8+U8+T8+S8+R8+Q8+P8+O8+N8+M8+L8+K8+J8+I8+H8+G8+F8+E8+D8+C8 -> 1000
A9: A1.4354 | B9: PA66GF30AKROM117 | BN9: =BM9+BL9+BK9+BJ9+BI9+BH9+BG9+BF9+BE9+BD9+BC9+BB9+BA9+AZ9+AY9+AX9+AW9+AV9+AU9+AT9+AS9+AR9+AQ9+AP9+AO9+AN9+AM9+AL9+AK9+AJ9+AI9+AH9+AG9+AF9+AE9+AD9+AC9+AB9+AA9+Z9+Y9+X9+W9+V9+U9+T9+S9+R9+Q9+P9+O9+N9+M9+L9+K9+J9+I9+H9+G9+F9+E9+D9+C9 -> 0
A10: A1.4377 | B10: PA6 ALCOM GF10 | G10: 2400 | BN10: =BM10+BL10+BK10+BJ10+BI10+BH10+BG10+BF10+BE10+BD10+BC10+BB10+BA10+AZ10+AY10+AX10+AW10+AV10+AU10+AT10+AS10+AR10+AQ10+AP10+AO10+AN10+AM10+AL10+AK10+AJ10+AI10+AH10+AG10+AF10+AE10+AD10+AC10+AB10+AA10+Z10+Y10+X10+W10+V10+U10+T10+S10+R10+Q10+P10+O10+N10+M10+L10+K10+J10+I10+H10+G10+F10+E10+D10+C10 -> 2400
A11: A1.4404 | B11: PBTGFH | BN11: =BM11+BL11+BK11+BJ11+BI11+BH11+BG11+BF11+BE11+BD11+BC11+BB11+BA11+AZ11+AY11+AX11+AW11+AV11+AU11+AT11+AS11+AR11+AQ11+AP11+AO11+AN11+AM11+AL11+AK11+AJ11+AI11+AH11+AG11+AF11+AE11+AD11+AC11+AB11+AA11+Z11+Y11+X11+W11+V11+U11+T11+S11+R11+Q11+P11+O11+N11+M11+L11+K11+J11+I11+H11+G11+F11+E11+D11+C11 -> 0
A12: A1.4425 | B12: PBTPETGF15DSP8T | C12: 200 | BN12: =BM12+BL12+BK12+BJ12+BI12+BH12+BG12+BF12+BE12+BD12+BC12+BB12+BA12+AZ12+AY12+AX12+AW12+AV12+AU12+AT12+AS12+AR12+AQ12+AP12+AO12+AN12+AM12+AL12+AK12+AJ12+AI12+AH12+AG12+AF12+AE12+AD12+AC12+AB12+AA12+Z12+Y12+X12+W12+V12+U12+T12+S12+R12+Q12+P12+O12+N12+M12+L12+K12+J12+I12+H12+G12+F12+E12+D12+C12 -> 200
A13: A1.5108 | B13: POM3807 | BN13: =BM13+BL13+BK13+BJ13+BI13+BH13+BG13+BF13+BE13+BD13+BC13+BB13+BA13+AZ13+AY13+AX13+AW13+AV13+AU13+AT13+AS13+AR13+AQ13+AP13+AO13+AN13+AM13+AL13+AK13+AJ13+AI13+AH13+AG13+AF13+AE13+AD13+AC13+AB13+AA13+Z13+Y13+X13+W13+V13+U13+T13+S13+R13+Q13+P13+O13+N13+M13+L13+K13+J13+I13+H13+G13+F13+E13+D13+C13 -> 0
A14: A1.5109 | B14: POM 588PWC-4D637 | M14: 200 | BN14: =BM14+BL14+BK14+BJ14+BI14+BH14+BG14+BF14+BE14+BD14+BC14+BB14+BA14+AZ14+AY14+AX14+AW14+AV14+AU14+AT14+AS14+AR14+AQ14+AP14+AO14+AN14+AM14+AL14+AK14+AJ14+AI14+AH14+AG14+AF14+AE14+AD14+AC14+AB14+AA14+Z14+Y14+X14+W14+V14+U14+T14+S14+R14+Q14+P14+O14+N14+M14+L14+K14+J14+I14+H14+G14+F14+E14+D14+C14 -> 200
A15: A1.5227 | B15: TPO CPREPND TD20 | BN15: =BM15+BL15+BK15+BJ15+BI15+BH15+BG15+BF15+BE15+BD15+BC15+BB15+BA15+AZ15+AY15+AX15+AW15+AV15+AU15+AT15+AS15+AR15+AQ15+AP15+AO15+AN15+AM15+AL15+AK15+AJ15+AI15+AH15+AG15+AF15+AE15+AD15+AC15+AB15+AA15+Z15+Y15+X15+W15+V15+U15+T15+S15+R15+Q15+P15+O15+N15+M15+L15+K15+J15+I15+H15+G15+F15+E15+D15+C15 -> 0
A16: A1.5230 | B16: PPC3122F-M117 | BN16: =BM16+BL16+BK16+BJ16+BI16+BH16+BG16+BF16+BE16+BD16+BC16+BB16+BA16+AZ16+AY16+AX16+AW16+AV16+AU16+AT16+AS16+AR16+AQ16+AP16+AO16+AN16+AM16+AL16+AK16+AJ16+AI16+AH16+AG16+AF16+AE16+AD16+AC16+AB16+AA16+Z16+Y16+X16+W16+V16+U16+T16+S16+R16+Q16+P16+O16+N16+M16+L16+K16+J16+I16+H16+G16+F16+E16+D16+C16 -> 0
A17: A1.5231 | B17: PPC3322T | BN17: =BM17+BL17+BK17+BJ17+BI17+BH17+BG17+BF17+BE17+BD17+BC17+BB17+BA17+AZ17+AY17+AX17+AW17+AV17+AU17+AT17+AS17+AR17+AQ17+AP17+AO17+AN17+AM17+AL17+AK17+AJ17+AI17+AH17+AG17+AF17+AE17+AD17+AC17+AB17+AA17+Z17+Y17+X17+W17+V17+U17+T17+S17+R17+Q17+P17+O17+N17+M17+L17+K17+J17+I17+H17+G17+F17+E17+D17+C17 -> 0
A18: A1.5232 | B18: PPC3322T -M125(JM8) | I18: 1000 | BN18: =BM18+BL18+BK18+BJ18+BI18+BH18+BG18+BF18+BE18+BD18+BC18+BB18+BA18+AZ18+AY18+AX18+AW18+AV18+AU18+AT18+AS18+AR18+AQ18+AP18+AO18+AN18+AM18+AL18+AK18+AJ18+AI18+AH18+AG18+AF18+AE18+AD18+AC18+AB18+AA18+Z18+Y18+X18+W18+V18+U18+T18+S18+R18+Q18+P18+O18+N18+M18+L18+K18+J18+I18+H18+G18+F18+E18+D18+C18 -> 1000
A19: A1.5260 | B19: PP +EPDM+T20EG299 | BN19: =BM19+BL19+BK19+BJ19+BI19+BH19+BG19+BF19+BE19+BD19+BC19+BB19+BA19+AZ19+AY19+AX19+AW19+AV19+AU19+AT19+AS19+AR19+AQ19+AP19+AO19+AN19+AM19+AL19+AK19+AJ19+AI19+AH19+AG19+AF19+AE19+AD19+AC19+AB19+AA19+Z19+Y19+X19+W19+V19+U19+T19+S19+R19+Q19+P19+O19+N19+M19+L19+K19+J19+I19+H19+G19+F19+E19+D19+C19 -> 0
A20: A1.5264 | B20: PPERC161NCN15926 | C20: -2750 | BN20: =BM20+BL20+BK20+BJ20+BI20+BH20+BG20+BF20+BE20+BD20+BC20+BB20+BA20+AZ20+AY20+AX20+AW20+AV20+AU20+AT20+AS20+AR20+AQ20+AP20+AO20+AN20+AM20+AL20+AK20+AJ20+AI20+AH20+AG20+AF20+AE20+AD20+AC20+AB20+AA20+Z20+Y20+X20+W20+V20+U20+T20+S20+R20+Q20+P20+O20+N20+M20+L20+K20+J20+I20+H20+G20+F20+E20+D20+C20 -> -2750
A21: A1.5313 | B21: PPGF30 HSBK011 | F21: 1000 | BN21: =BM21+BL21+BK21+BJ21+BI21+BH21+BG21+BF21+BE21+BD21+BC21+BB21+BA21+AZ21+AY21+AX21+AW21+AV21+AU21+AT21+AS21+AR21+AQ21+AP21+AO21+AN21+AM21+AL21+AK21+AJ21+AI21+AH21+AG21+AF21+AE21+AD21+AC21+AB21+AA21+Z21+Y21+X21+W21+V21+U21+T21+S21+R21+Q21+P21+O21+N21+M21+L21+K21+J21+I21+H21+G21+F21+E21+D21+C21 -> 1000
A22: A1.5157 | B22: POM M9044 | BN22: =BM22+BL22+BK22+BJ22+BI22+BH22+BG22+BF22+BE22+BD22+BC22+BB22+BA22+AZ22+AY22+AX22+AW22+AV22+AU22+AT22+AS22+AR22+AQ22+AP22+AO22+AN22+AM22+AL22+AK22+AJ22+AI22+AH22+AG22+AF22+AE22+AD22+AC22+AB22+AA22+Z22+Y22+X22+W22+V22+U22+T22+S22+R22+Q22+P22+O22+N22+M22+L22+K22+J22+I22+H22+G22+F22+E22+D22+C22 -> 0
A23: A1.5193 | B23: PP A422 GM304C | BN23: =BM23+BL23+BK23+BJ23+BI23+BH23+BG23+BF23+BE23+BD23+BC23+BB23+BA23+AZ23+AY23+AX23+AW23+AV23+AU23+AT23+AS23+AR23+AQ23+AP23+AO23+AN23+AM23+AL23+AK23+AJ23+AI23+AH23+AG23+AF23+AE23+AD23+AC23+AB23+AA23+Z23+Y23+X23+W23+V23+U23+T23+S23+R23+Q23+P23+O23+N23+M23+L23+K23+J23+I23+H23+G23+F23+E23+D23+C23 -> 0
A24: A1.5195 | B24: PP A422L630 | H24: 1000 | BN24: =BM24+BL24+BK24+BJ24+BI24+BH24+BG24+BF24+BE24+BD24+BC24+BB24+BA24+AZ24+AY24+AX24+AW24+AV24+AU24+AT24+AS24+AR24+AQ24+AP24+AO24+AN24+AM24+AL24+AK24+AJ24+AI24+AH24+AG24+AF24+AE24+AD24+AC24+AB24+AA24+Z24+Y24+X24+W24+V24+U24+T24+S24+R24+Q24+P24+O24+N24+M24+L24+K24+J24+I24+H24+G24+F24+E24+D24+C24 -> 1000
A25: A1.5228 | B25: PP C332EF M12FCB | BN25: =BM25+BL25+BK25+BJ25+BI25+BH25+BG25+BF25+BE25+BD25+BC25+BB25+BA25+AZ25+AY25+AX25+AW25+AV25+AU25+AT25+AS25+AR25+AQ25+AP25+AO25+AN25+AM25+AL25+AK25+AJ25+AI25+AH25+AG25+AF25+AE25+AD25+AC25+AB25+AA25+Z25+Y25+X25+W25+V25+U25+T25+S25+R25+Q25+P25+O25+N25+M25+L25+K25+J25+I25+H25+G25+F25+E25+D25+C25 -> 0
A26: A1.5233 | B26: PP C33207 M12F | BN26: =BM26+BL26+BK26+BJ26+BI26+BH26+BG26+BF26+BE26+BD26+BC26+BB26+BA26+AZ26+AY26+AX26+AW26+AV26+AU26+AT26+AS26+AR26+AQ26+AP26+AO26+AN26+AM26+AL26+AK26+AJ26+AI26+AH26+AG26+AF26+AE26+AD26+AC26+AB26+AA26+Z26+Y26+X26+W26+V26+U26+T26+S26+R26+Q26+P26+O26+N26+M26+L26+K26+J26+I26+H26+G26+F26+E26+D26+C26 -> 0
A27: A1.5236 | B27: PP C654OL-638B | BN27: =BM27+BL27+BK27+BJ27+BI27+BH27+BG27+BF27+BE27+BD27+BC27+BB27+BA27+AZ27+AY27+AX27+AW27+AV27+AU27+AT27+AS27+AR27+AQ27+AP27+AO27+AN27+AM27+AL27+AK27+AJ27+AI27+AH27+AG27+AF27+AE27+AD27+AC27+AB27+AA27+Z27+Y27+X27+W27+V27+U27+T27+S27+R27+Q27+P27+O27+N27+M27+L27+K27+J27+I27+H27+G27+F27+E27+D27+C27 -> 0
A28: A1.5326 | B28: PP H1407R | L28: 500 | BN28: =BM28+BL28+BK28+BJ28+BI28+BH28+BG28+BF28+BE28+BD28+BC28+BB28+BA28+AZ28+AY28+AX28+AW28+AV28+AU28+AT28+AS28+AR28+AQ28+AP28+AO28+AN28+AM28+AL28+AK28+AJ28+AI28+AH28+AG28+AF28+AE28+AD28+AC28+AB28+AA28+Z28+Y28+X28+W28+V28+U28+T28+S28+R28+Q28+P28+O28+N28+M28+L28+K28+J28+I28+H28+G28+F28+E28+D28+C28 -> 500
A29: A1.5328 | B29: PP11FX TYC1152PBK | BN29: =BM29+BL29+BK29+BJ29+BI29+BH29+BG29+BF29+BE29+BD29+BC29+BB29+BA29+AZ29+AY29+AX29+AW29+AV29+AU29+AT29+AS29+AR29+AQ29+AP29+AO29+AN29+AM29+AL29+AK29+AJ29+AI29+AH29+AG29+AF29+AE29+AD29+AC29+AB29+AA29+Z29+Y29+X29+W29+V29+U29+T29+S29+R29+Q29+P29+O29+N29+M29+L29+K29+J29+I29+H29+G29+F29+E29+D29+C29 -> 0
A30: A1.5345 | B30: PP MD20 ECO | BN30: =BM30+BL30+BK30+BJ30+BI30+BH30+BG30+BF30+BE30+BD30+BC30+BB30+BA30+AZ30+AY30+AX30+AW30+AV30+AU30+AT30+AS30+AR30+AQ30+AP30+AO30+AN30+AM30+AL30+AK30+AJ30+AI30+AH30+AG30+AF30+AE30+AD30+AC30+AB30+AA30+Z30+Y30+X30+W30+V30+U30+T30+S30+R30+Q30+P30+O30+N30+M30+L30+K30+J30+I30+H30+G30+F30+E30+D30+C30 -> 0
A31: A1.5357 | BN31: =BM31+BL31+BK31+BJ31+BI31+BH31+BG31+BF31+BE31+BD31+BC31+BB31+BA31+AZ31+AY31+AX31+AW31+AV31+AU31+AT31+AS31+AR31+AQ31+AP31+AO31+AN31+AM31+AL31+AK31+AJ31+AI31+AH31+AG31+AF31+AE31+AD31+AC31+AB31+AA31+Z31+Y31+X31+W31+V31+U31+T31+S31+R31+Q31+P31+O31+N31+M31+L31+K31+J31+I31+H31+G31+F31+E31+D31+C31 -> 0
A32: A1.5358 | B32: PP-T20A5132T(JM8) | BN32: =BM32+BL32+BK32+BJ32+BI32+BH32+BG32+BF32+BE32+BD32+BC32+BB32+BA32+AZ32+AY32+AX32+AW32+AV32+AU32+AT32+AS32+AR32+AQ32+AP32+AO32+AN32+AM32+AL32+AK32+AJ32+AI32+AH32+AG32+AF32+AE32+AD32+AC32+AB32+AA32+Z32+Y32+X32+W32+V32+U32+T32+S32+R32+Q32+P32+O32+N32+M32+L32+K32+J32+I32+H32+G32+F32+E32+D32+C32 -> 0
A33: A1.5380 | B33: PP TD17 BMV214W | L33: 700 | BN33: =BM33+BL33+BK33+BJ33+BI33+BH33+BG33+BF33+BE33+BD33+BC33+BB33+BA33+AZ33+AY33+AX33+AW33+AV33+AU33+AT33+AS33+AR33+AQ33+AP33+AO33+AN33+AM33+AL33+AK33+AJ33+AI33+AH33+AG33+AF33+AE33+AD33+AC33+AB33+AA33+Z33+Y33+X33+W33+V33+U33+T33+S33+R33+Q33+P33+O33+N33+M33+L33+K33+J33+I33+H33+G33+F33+E33+D33+C33 -> 700
A34: A1.5386 | B34: PPTYC 852P | BN34: =BM34+BL34+BK34+BJ34+BI34+BH34+BG34+BF34+BE34+BD34+BC34+BB34+BA34+AZ34+AY34+AX34+AW34+AV34+AU34+AT34+AS34+AR34+AQ34+AP34+AO34+AN34+AM34+AL34+AK34+AJ34+AI34+AH34+AG34+AF34+AE34+AD34+AC34+AB34+AA34+Z34+Y34+X34+W34+V34+U34+T34+S34+R34+Q34+P34+O34+N34+M34+L34+K34+J34+I34+H34+G34+F34+E34+D34+C34 -> 0
A35: A1.5388 | B35: PP/EPD121 | BN35: =BM35+BL35+BK35+BJ35+BI35+BH35+BG35+BF35+BE35+BD35+BC35+BB35+BA35+AZ35+AY35+AX35+AW35+AV35+AU35+AT35+AS35+AR35+AQ35+AP35+AO35+AN35+AM35+AL35+AK35+AJ35+AI35+AH35+AG35+AF35+AE35+AD35+AC35+AB35+AA35+Z35+Y35+X35+W35+V35+U35+T35+S35+R35+Q35+P35+O35+N35+M35+L35+K35+J35+I35+H35+G35+F35+E35+D35+C35 -> 0
A36: A1.5420 | B36: PP+EPPM+T20 | BN36: =BM36+BL36+BK36+BJ36+BI36+BH36+BG36+BF36+BE36+BD36+BC36+BB36+BA36+AZ36+AY36+AX36+AW36+AV36+AU36+AT36+AS36+AR36+AQ36+AP36+AO36+AN36+AM36+AL36+AK36+AJ36+AI36+AH36+AG36+AF36+AE36+AD36+AC36+AB36+AA36+Z36+Y36+X36+W36+V36+U36+T36+S36+R36+Q36+P36+O36+N36+M36+L36+K36+J36+I36+H36+G36+F36+E36+D36+C36 -> 0
A37: A1.5422 | B37: PP+EPPM+TD20 | BN37: =BM37+BL37+BK37+BJ37+BI37+BH37+BG37+BF37+BE37+BD37+BC37+BB37+BA37+AZ37+AY37+AX37+AW37+AV37+AU37+AT37+AS37+AR37+AQ37+AP37+AO37+AN37+AM37+AL37+AK37+AJ37+AI37+AH37+AG37+AF37+AE37+AD37+AC37+AB37+AA37+Z37+Y37+X37+W37+V37+U37+T37+S37+R37+Q37+P37+O37+N37+M37+L37+K37+J37+I37+H37+G37+F37+E37+D37+C37 -> 0
A38: A1.4166 | B38: ABS HH106 | C38: 200 | BN38: =BM38+BL38+BK38+BJ38+BI38+BH38+BG38+BF38+BE38+BD38+BC38+BB38+BA38+AZ38+AY38+AX38+AW38+AV38+AU38+AT38+AS38+AR38+AQ38+AP38+AO38+AN38+AM38+AL38+AK38+AJ38+AI38+AH38+AG38+AF38+AE38+AD38+AC38+AB38+AA38+Z38+Y38+X38+W38+V38+U38+T38+S38+R38+Q38+P38+O38+N38+M38+L38+K38+J38+I38+H38+G38+F38+E38+D38+C38 -> 200
