Workbook

Sheet Front Matter
A1: Statement of Work (eSOW/Hardware)
A2: JLR-TMP-557249 Issue Level 5.1 | H2: Revision | I2: {=LOOKUP(2,1/(A108:A118<>""),A108:A118)} -> 2 | J2: {=LOOKUP(2,1/(B108:B118<>""),B108:B118)} -> Third Submission
A4: RECORDS MANAGEMENT
A5: TITLE: | B5: Engineering Statement of Work | E5: RETENTION No: | G5: CP1-001 | I5: OWNER: | J5: Marcus Penn
A6: SECURITY: | B6: CONFIDENTIAL | E6: RECORD TYPE: | G6: OFFICIAL | I6: AUTHOR: | J6: Phil MacRae
A7: This Statement of Work shall be used to define the project and technical requirements for any given sourcing project and to support the Global Sourcing Process requirements at Jaguar Land Rover. This document is the authoritative document for all engineering, technical and software requirements. Requirements defined in any other Supplemental Statement of Work (referred to as sow hereinafter) documents shall not supersede the content of this Statement of Work unless stated otherwise.
A8: Document Title: | C8: L463 30MY Injection Moulded PANELS | G8: Supplier Category: | I8: Make to Print
A9: Centre of Competence: | C9: Body Engineering | G9: Vehicle Platform: | I9: MLA
A10: Squad / Chapter: | C10: Cabin | G10: Vehicle Line / Name: | I10: L463
A11: Job #1 Date | C11: 47126 | G11: Model Year: | I11: 30MY
A12: Supplier Master Code: | G12: Supplier Name:
A14: Lead Engineer: | C14: Marton Minda | E14: CDSID: | F14: mminda1 | G14: GSPid Code: | I14: IN_10322
A15: Group Leader: | C15: Marek Pyka | E15: CDSID: | F15: mpyka | G15: Commodity Plan: | I15: L463 30MY IM PANELS
A16: Module Lead: | C16: Mark Croucher | E16: CDSID: | F16: mcrouch7 | G16: Commodity Plan Code: | I16: P-0008384
A17: Strategic Buyer: | C17: Lauren Spensley | E17: CDSID: | F17: lspensl1 | G17: Component / System: | I17: Floor Coverings
A18: Service Lead: | C18: Mark Hardy | E18: CDSID: | F18: mhardy28 | G18: CPSCII Code: | I18: 010501
A21: SIGNATURES BLOCK
A22: Jaguar Land Rover Lead Engineer:
A23: Name: | B23: =C14 -> Marton Minda | D23: CDSID: | E23: =F14 -> mminda1 | F23: DATE: | H23: SIGNED:
A26: Jaguar Land Rover Module Leader:
A27: Name: | B27: =C16 -> Mark Croucher | D27: CDSID: | E27: =F16 -> mcrouch7 | F27: DATE: | H27: SIGNED:
A30: Authorising Service Signatory: *This signatory is mandatory. Contact Mark Hardy (mhardy28) for direction and guidance.
A31: Name: | B31: =C18 -> Mark Hardy | D31: CDSID: | E31: =F18 -> mhardy28 | F31: DATE: | H31: SIGNED:
A34: Supplier Representing Engineer:
A35: Name: | D35: ID No: | F35: DATE: | H35: SIGNED:
A41: Record of Changes to JLR-TMP-557249 Template
A42: This section contains a detailed list of all changes to the template. The use of this section is reserved for use by the Content Author and the Content Owner as defined in JLR Way in accordance with the Statement of Work (eSOW/Hardware) JLR-TMP-557249 operational template. This section must not be changed or edited by any signature of the Statement of Work.
A43: ISSUE LEVEL | B43: ISSUE CHANGE | C43: CHANGE TYPE | D43: LOCATION TAB / APPENDIX | F43: DESCRIPTION
A44: 3.0 | B44: MAJOR | C44: N/A | D44: ALL | F44: The Statement of Work has been overhauled, 100% content revision.
A45: 3.1 | B45: MINOR | C45: NEW | D45: ALL | F45: Sticky Notes added to section titles for guidance and clarity of instruction. Not visible to supplier when printed to .pdf format.
C46: NEW | D46: ELECTRICAL REQUIREMENTS | F46: Added Cyber Security Section.
A47: 3.2 | B47: MINOR | C47: CHANGE | D47: FRONT MATTER | F47: Improvements to Warranty Terms and Conditions Section.
C48: CHANGE | D48: FRONT MATTER | F48: Changes to 3DX License Requirements within Core Applications Section.
A49: 3.3 | B49: MINOR | C49: NEW | D49: APPENDIX G | F49: New Appendix added (H) for Semiconductor sourcing requirements.
C50: CHANGE | D50: HARDWARE / CAD | F50: Hardware Requirements Tab updated to include Hardware technical requirements and all CAD/CAE requirements.
C51: CHANGE | D51: ELECTRICAL REQUIREMENTS | F51: Revised to only define Cyber Security, Electrical Connectors and Bespoke requirements. Other information captured in Tab Technical Requirements.
A52: 3.4 | B52: MINOR | C52: CHANGE | D52: FRONT MATTER | F52: Official Records Statement and Retention Code update to reflect correct JLR Official Records Policy.
C53: DELETED | D53: FRONT MATTER | F53: Hyperlinks to sources outside of the Statement of Work deleted due to problems with access needs, site security and excel.
A54: 3.5 | B54: MINOR | C54: NEW | D54: FRONT MATTER | F54: Flash Page replaced with new version; directly Infront of Signature block on Page 1.
C55: NEW | D55: FRONT MATTER | F55: Reference changed in Parts Development and Validation. Prototype Part Governance Process changed from JLR-PRD-557143 to JLR-PRD-557806.
...

Sheet DATA_NEW
A1: SUPPLIER CATEGORIES | I1: LOCATIONS | M1: SKILLS | O1: REVISION | P1: SUBMISSION
A2: Engineering Service Provider | I2: NOT APPLICABLE | M2: 3D Experience | O2: 1 | P2: Second Submission
A3: Full System Provider | I3: BRAZIL | M3: ACDS | O3: 2 | P3: Third Submission
A4: Assembly or Component Provider | I4: BROWNS LANE | M4: Agile | O4: 3 | P4: Fourth Submission
A5: Consultancy Component Provider | I5: CASTLE BROMWICH | M5: Agile QBR management process | O5: 4 | P5: Fifth Submission
A6: Make to Print | I6: CHINA | M6: AIMS - Process Awareness, Resolution | O6: 5 | P6: Sixth Submission
A7: ESP_DOOR TRIM | I7: EMC | M7: AIMS2 | O7: 6 | P7: Seventh Submission
I8: GAYDON | M8: Bill of Material | O8: 7 | P8: Eighth Submission
A9: CORE APPLICATIONS | I9: GRAZ | M9: Business Objects 4.2 | O9: 8 | P9: Ninth Submission
A10: APP | B10: ESI | C10: ESP | D10: FSP | E10: ASSY COM | F10: CONSULT | G10: MTP | H10: ESP_DOOR TRIM | I10: HALEWOOD | M10: C/C++ | O10: 9 | P10: Tenth Submission
A11: 3DX | B11: MANDATORY | C11: MANDATORY | D11: MANDATORY | E11: MANDATORY | F11: MANDATORY | G11: MANDATORY | H11: MANDATORY | I11: INDIA (PUNE) | M11: CAD | O11: 10 | P11: Eleventh Submission
A12: AIMS2 | B12: MANDATORY | C12: MANDATORY | D12: MANDATORY | E12: MANDATORY | F12: MANDATORY | G12: MANDATORY | H12: MANDATORY | I12: OXFORD ROAD | M12: CAE
A13: eAPQP | B13: NOT APPLIC. | C13: NOT APPLIC. | D13: MANDATORY | E13: MANDATORY | F13: MANDATORY | G13: MANDATORY | H13: MANDATORY | I13: SLOVAKIA (NITRA) | M13: CAS / CAM | O13: EMC DATA
A14: EnerjyHub | B14: MANDATORY | C14: MANDATORY | D14: MANDATORY | E14: MANDATORY | F14: MANDATORY | G14: MANDATORY | H14: MANDATORY | I14: SOLIHULL | M14: Catia V5 | O14: COMM. TYPE
A15: ePSW | B15: NOT APPLIC. | C15: NOT APPLIC. | D15: MANDATORY | E15: MANDATORY | F15: MANDATORY | G15: MANDATORY | H15: MANDATORY | I15: WHITLEY | M15: Catia V6 | O15: COMPONENT
A16: RMDV2 | B16: MANDATORY | C16: MANDATORY | D16: MANDATORY | E16: NOT APPLIC. | F16: NOT APPLIC. | G16: NOT APPLIC. | H16: NOT APPLIC. | M16: CCDS | O16: SUB-SYSTEM
A17: JIRA | B17: MANDATORY | C17: MANDATORY | D17: MANDATORY | E17: MANDATORY | F17: MANDATORY | G17: MANDATORY | H17: MANDATORY | M17: Change Decision Forum/ Scope Control | O17: DESIGN STAT.
A18: Confleunce | B18: MANDATORY | C18: MANDATORY | D18: MANDATORY | E18: MANDATORY | F18: MANDATORY | G18: MANDATORY | H18: MANDATORY | M18: Clipboards | O18: NEW
M19: Commodity Strategy L1 & L2 | O19: CARRY OVER
A20: APPLIC TABLE | D20: CAD CAE | E20: ESI | F20: ESP | G20: FSP | H20: ASSY | I20: CONSULT | J20: MTP | M20: Communication & Presentation Skills | O20: COMBO
A21: YES | D21: JLR-Q1 | M21: Confluence | O21: CARRY OVER w/CHANGE
A22: NO | D22: JLR-Q2 | M22: Current Veh. - Quality Metrics & Issue Mgmt
A23: Y | D23: JLR-Q3 | M23: Customer Feature change governance | O23: EMC_1.1 | Q23: ACCESS PORTAL
A24: N | D24: SUP-Q1 | M24: DTC's / Warning messages | O24: EMC_1.2 | Q24: DASSAULT 3D EXPERIENCE
A25: APPLICABLE | D25: SUP-Q2 | M25: eAPQP | O25: EMC_1.3 | Q25: Majenta EnerjyHub
A26: NOT APPLICABLE | D26: SUP-Q3 | M26: EBOM | O26: EMC_1.4 | Q26: OPTION 3
A27: REQUIRED | M27: EDS Clearplan | O27: EMC_1.5 | Q27: OPTION 4
A28: NOT REQUIRED | D28: RESPONSIBILITY | H28: NEW | J28: STANDARDS | M28: eFDVS | O28: EMC_1.6
A29: MANDATORY | D29: JAGUAR LAND ROVER | H29: CARRY OVER | J29: INDUSTRY | M29: EnerjyHub | O29: EMC_1.7
A30: NOT APPLICABLE | D30: SUPPLIER | H30: NTEI | J30: JLR | M30: Engineering Standards | O30: EMC_1.8
D31: TIER 1 SUPPLIER | H31: N/A | M31: ePSW | O31: EMC_1.9
D32: TIER 2 SUPPLIER | J32: TYPE | M32: Evidence Base Engineering Release (EBER) | O32: EMC_1.10
A33: Jaguar Land Rover Ltd | J33: HARDWARE | M33: Exalead (Developer) | O33: EMC_1.11
A34: Supplier | J34: CAD/CAE | M34: Exalead (End user) | O34: EMC_1.12
J35: ELECTRICAL | M35: Excel | O35: EMC_1.13
A36: Special Mandatory for Cyber | D36: CHAGE TYPE | J36: CYBER | M36: Feature code knowledge (ACE, rMFD) | O36: EMC_1.14
A37: MANDATORY SOFTWARE IN SCOPE | D37: NEW | J37: SOFTWARE | M37: Features & System Delivery Process (SSCD) | O37: EMC_1.15
A38: NOT APPLICABLE SOFTWARE NOT IN SCOPE | D38: CHANGE | J38: MISC. | M38: FMEA
D39: DELETED | M39: Gateway Papers
M40: Git | O40: Partner TAB ALIGNMEN
...

Sheet Supply Chain Transparency
A1: Supply Chain Transparency Requirements
A2: JLR and the Supplier are expected to work under a bi-lateral agreement where JLR may request the supplier to provide visibility into supplier upstream supply chain(s) to ensure that both JLR and the supplier are working to accepted industry practice in key areas as defined below in section SCRT.1 Areas of Transparency. In some cases, the supplier may be requested to provide demonstrations and evidence of their ability to meet transparency requirement targets as defined below.
A4: SCTR.1 Areas of Transparency
A6: AREA | C6: REQUIREMENT | H6: TARGET
A7: HIGH RISK COMPONENTS | C7: To be completed by JLR Define a list of high risk components for the particular supplier | H7: To be completed by JLR Define the level of information / type of data and the method of exchange required to satisfy
A8: SUSTAINABILITY | C8: To be completed by JLR Define a list of sustainability requirements | H8: To be completed by JLR Define sustainability targets, including where applicable EU regulation or international standards.
A9: ETHICAL PRACTICES | C9: To be completed by JLR Define a list of ethical practices or standards | H9: To be completed by JLR Define targets in accordance with local, nation or international guidelines or governance
A10: Spare | C10: For JLR Only Use this row to define additional transparency requirements.
A11: Spare | C11: For JLR Only Use this row to define additional transparency requirements.
A12: Spare | C12: For JLR Only Use this row to define additional transparency requirements.
A14: SCTR.2 Supply Chain Transparency Lead / Point of Contact
A15: JLR invites the supplier to nominate an individual, or department to act as a liaison between JLR and the supplier relating to all matters defined above. The nominated individual or department is not required to be defined as a technical expert in any area defined above, however is expected act in the best interest of transparency, openness, integrity and to continue the completion of all targets in the spirit of good supplier behaviour practices and open collaboration with JLR.
A17: Supplier Representing Transparency Point of Contact:
A18: Name: | D18: ID No: | F18: DATE: | H18: SIGNED:
E21: END OF SECTION

Sheet Environmental Req.
A1: Environmental and Recycling Requirements
A2: Suppliers of production materials, equipment, services and consumption goods play a vital part in the development and production of Jaguar Land Rover products. Therefore, all goods and services supplied to Jaguar Land Rover shall be aligned with the Jaguar Land Rover Environmental Requirements and any applicable legislation. Supplied parts and services shall comply with the environmental targets as detailed in the Sourcing and Commercial Programme Agreement (SCPA), Engineering Statements of Work, Advanced Product Quality Planning (APQP) Requirements and Guidelines, JLR Global Sustainability Web Guide – Supplier Environmental & Social Requirements, System or Vehicle Design Specifications and the program specific targets. All legislation must be fulfilled and complied with. Jaguar Land Rover requires all production and non-production suppliers with manufacturing facilities third party certify all facilities to ISO 14001. Parts must comply with the environmental targets as detailed below. All engineering standards such as STJLRs shall be made available to the supplier through the Enerjyhub system.
A4: ERR.1 Restricted Substances and Materials of Concern
A5: REQUIREMENT | C5: All parts shall comply with the Restricted Substance Management Standard (RSMS) STJLR.99.9999. The supplier shall fulfil and comply with the reporting requirements in the Prohibited and Declarable Substances table in STJLR.99.9999. The Supplier is responsible to make sure that all their parts conform to the End-Of-Life Vehicles (ELV) legislation. The supplier shall support JLR or international material phase-out strategies.
A6: TIMING | C6: Where required, the supplier shall submit a compliance plan 30 days before the most up to date, and understood PRDJ date through the RMDV access portal. Full International Material Data System (IMDS) data is required prior to CSO for all non-tuneable parts and VSSO for all tuneable and non-tuneable parts. Refer to the IMDS Submission Guide For Suppliers to Jaguar Land Rover. This guide is located in Enerjyhub.
A7: TARGET | C7: All parts must comply with the RSMS standard STJLR.99.9999. Non exempted components containing Lead, Mercury, Cadmium and Hexavalent Chromium are prohibited. Suppliers shall identify lead in solder application codes according to Appendix G. Lead-Free Solder Checklist to enable compliance with Annex II, 2000/53/EC. The Supplier shall comply with STJLR.50.5353. Companies who distribute brominated flame retardants and the users of these retardants are advised to subscribe to the VECAP programme (www.vecap.info) to reduce emissions into the environment. Tier 1 suppliers to Jaguar Land Rover shall cascade these requirements, rules and advisements to Tier 2 suppliers and all other affected suppliers.
A9: ERR.2 Vehicle Recyclability - Parts Reuse Restrictions
A10: REQUIREMENT | C10: Do not supply any re-used parts for production of vehicles which are prohibited in Annex V of Recyclability Type Approval Directive 2005/64/EC in its latest amended version.
A11: TIMING | C11: Before JOB #1.
A12: TARGET | C12: To Comply with Annex V of the Recyclability Type Approval Directive 2005/64/EC.
A14: ERR.3 Vehicle Recyclability - Design
A15: REQUIREMENT | C15: Increase the recyclable share of the vehicle that is economically viable. Promote the use of mono-material usage in components where possible, followed by use of mechanical fixings between materials to promote pre-shredding material separation and reduce contamination.
A16: TIMING | C16: For recyclability, refer to RSMS STJLR.99.9999 Section H, for IMDS reporting timing. For materials recyclability test case, parts must be assessed prior to EDJ to enable any material compatibility/ recyclability issues to be resolved.
A17: TARGET | C17: To support Vehicle Recyclability as measured by method (ISO 22628), required for whole vehicle type approval, material composition is to be reported via IMDS in accordance with RSMS requirements. Ref example parts in Table 4 that should be designed to be recyclable.
A18: ERR.4 Parts Marking
A19: REQUIREMENT | C19: All plastic and elastomeric parts shall be marked for recycling.
A20: TIMING | C20: To comply with the parts marking requirements of the End of Life Vehicle Directive 2000/53/EC, polymeric components exceeding 100 grams and elastomeric components exceeding 200 grams are required to be marked according to ISO 1043 Part 1 and Part 2, ISO 11469 or ISO 1629. The CAD shall include the polymeric parts marking symbols and identify their correct location on the part before PRDJ.
A21: TARGET | C21: All plastic & elastomeric parts to be marked as identified. Refer to ISO standards: ISO 1043-1, 1043-2 and 11469 for plastics and ISO 1629 for rubber materials. Above 100 grams for plastics and above 200 grams for elastomers. The parts marking symbol and the parts marking check box shall be accurately recorded in the IMDS submission for the part.
A23: ERR.5 Recycled Materials
A24: REQUIREMENT | C24: The Supplier shall identify opportunities to incorporate post-consumer recycled (PCR) content(closed loop prioritised) and post-industrial recycled (PIR) / pre-consumer recycled material content into appropriate components. For new programmes from 29MY onwards, all parts must comply with the requirements defined in STJLR.51.5270 V3 Use of Recycled Material in Polymers, Aluminium, Steel and Glass. Programme's prior to this, will comply to STJLR 51.5270 V2. Any MCF/unit programme's where by opportunities to use recycled content are available, these should be explored. Potential applications should be identified and shall be pursued and evaluated with the relevant JLR Materials Engineer / JLR Sustainability Programme Integration Lead, in order to comply with vehicle targets. Home scrap recycling is not accepted as recycled content. Refer to ISO 14021.
A25: TIMING | C25: Supplier to notify JLR Lead Engineer of any issues in meeting the requirement before FR/EDC. Component specification/drawing to include recycled content at EDC, final confirmation from supplier and entry into IMDS with confirmed recycled content included as evidence via RMDV by CSO.
A26: TARGET | C26: New programme's from 29MY onwards shall meet the respective CPSC level recycled content target for specified material families as per STJLR 51.5270 V3 or exception agreed by JLR Materials Engineering & Product Sustainability. Parts that already contain recycled content should continue to be specified in the same manner and aim to increase the recycled content % and/or include PCR content where possible as specified in STJLR.51.5270 V3. Any programmes prior to 29MY shall target a minimum 20% recycled content for all polymer material, if not, exception to be agreed by JLR Materials Engineering and Product Sustainability. Example target parts for recycled polymer content are listed in section ERR.11 below. Parts that already contain recycled content should continue to be specified in the same manner and increased by 10% where possible as specified in STJLR.51.5270 V2. Any MCF or unit programmes which does not have a programme level target, but does contain opportunity to introduce recycled content should be explored. At the request of Jaguar Land Rover, the Supplier shall provide evidence (via RMDV and IMDS, using the recycled tab) of recycled material content.
A28: ERR.6 Vehicle Interior Environment Quality (VIEQ)
A29: REQUIREMENT | C29: To comply with Volatile Organic compounds (VOC) emission targets within the interior cabin, the supplier shall use low VOC emission materials TÜV TOXPROOF. The Supplier shall, where appropriate, use materials within vehicle interior cabin that do not have any adverse impacts to health in accordance with the requirements in STJLR.51.5232. The supplier shall test and record results for air filtration components in accordance with TÜV TOXPROOF Criteria Catalogue, 2 PIG S 0051.
A30: TIMING | C30: The supplier shall notify the JLR Lead Engineer and relevant Materials Engineer of any issues or obstacle that will, or may prevent the supplier or Jaguar Land Rover to meet the requirements defined in the standard before FR, Final material testing and sign off before PRC, Final component testing and sign off before VSSO. The supplier shall record issues or obstacles via RMDV or by any other approved collaboration means agreed in the Project Management Section of this Statement of Work. The supplier shall support Jaguar Land Rover, when requested, to investigate components if required to meet vehicle level requirement. Skin contact materials to be tested by TUV Rheinland at PRDJ.
A31: TARGET | C31: Materials shall comply with the requirements defined in STJLR.51.5229. Applicable components shall comply with the requirements defined in STJLR.01.5202. “Skin Contact” Materials to comply with the requirements defined in STJLR.51.5232., and to be tested by TUV Rheinland and approved to their TOXPROOF Criteria catalogue.
A33: ERR.7 List of Affected Commodities
A34: REQUIREMENT | G34: AFFECTED COMMODITY
A35: Restricted Substance Management Standard | G35: All
A36: Recyclability | G36: All commodities except for parts listed in "Example Parts Identified For Recycling" Section below.
A37: Parts Marking | G37: All non-metallic parts as identified in ISO standards ISO 1043-1, 1043-2 and 11469 for plastics and ISO 1629 for rubber materials (plastics above 100 grams, elastomers above 200 grams).
A38: Recycled Materials (PCR, PIR) | G38: All components that contain polymers.
A39: Vehicle Interior Environment Quality (VIEQ) | G39: All interior parts, exterior door handles and tailgate.
A41: ERR.8 Parts Identified for Pre-Treatment
A42: Plans are required for the parts defined below to make sure that Jaguar Land Rover vehicles comply with ELV dismantling requirements.
A43: COMMODITY | G43: ACTION
A44: Parts listed in the EU ELV directive Annex I / II: - All batteries - All electronic circuit boards and other electronic components if a vehicle threshold of 60g of lead in solder is exceeded - Tyres - Electrical components which contain lead in solder or in a glass or ceramic matrix compound except glass in bulbs and glaze of spark plugs if a vehicle threshold of 60g lead is exceeded - Supercapacitors / Ultracapacitors / Electrochemical double-layer capacitors (EDLCs) | G44: Design for Disassembly actions (easy access, safe and easy removal).
A45: Pyrotechnic systems | G45: Minimum time to deploy / neutralise all devices through use of ECU or OBD connected tooling, easy access to the ECU, provision of dismantling manuals is required. New dismantling manuals are required where changes to the dismantling processes are made with MY updates.
A46: All fluid containing components | G46: Fluid removal marking, easy access. Design of component must ensure all fluid can be removed within 20 mins using gravity or suction methods.
A47: Electronics | G47: Efficient soldering techniques should be employed to reduce lead content in components. Use energy efficient components. Refer to Appendix G. Lead Free Solder Checklist for more information.
...

Sheet Project Management
A1: Project Management
A3: SUPPLIER CATEGORY | E3: ='Front Matter'!I8 -> Make to Print
A4: This Section shall be used if the commodity to be sourced is a physical part, structure or system with no software or electrical parts. The Lead Engineer is responsible for the completion of all sections within this Statement of Work. Contact the relevant Buyer for volumes, Vehicle Programme Framework documents or other relevant project information.
A5: This section defines all information relating to the project management aspect of the sourcing project. Jaguar Land Rover shall provide the supplier with the most mature and relevant project and programme information applicable to the creation of a clear and concise Request For Quotation and receive a realistic and achievable quotation from a supplier.
A6: EPM.1 Vehicle Information
A7: Not all fields in this section may be applicable or mandatory for the sourcing requirements defined in this document, however it is recommended to complete as much information in this section for familiarisation, understanding and applicability. If any field in this section is not applicable, then enter (or select) "NOT APPLICABLE" in the respective field.
A8: CYCLE PLAN CODE | D8: VEHICLE NAME | G8: JOB #1 DATE | J8: PROGRAM SCALE
A9: Y9250 | D9: L463 | G9: 47098 | J9: 8 years
A11: MANUF. LOCATION | D11: LIFECYCLE TOTAL | G11: MANUF. LOCATION | J11: PEAK ANNUAL VOLUME
A12: Nitra | D12: 626000 | G12: Nitra | J12: 92000
B14: POWERTRAIN | G14: WHEELBASE
B15: CODE | D15: DESCRIPTION | G15: CODE | I15: DESCRIPTION
B16: - | D16: - | G16: - | I16: -
B18: CAB STYLE | G18: TRANSMISSION
B19: CODE | D19: DESCRIPTION | G19: CODE | I19: DESCRIPTION
B20: - | D20: - | G20: - | I20: -
B22: PROJECT LOCATIONS
B23: ASSEMBLY LOCATION | E23: PTO PLANT LOCATION | H23: PROTOTYPE BUILD LOCATION
B24: SLOVAKIA (NITRA) | E24: OXFORD ROAD | H24: OXFORD ROAD
A26: EPM.2 Programme Timings
A27: All programs must use and be aligned to PCDS V4 gateways, milestones, events and timelines. Where fixed dates are not available, the Lead Engineer shall apply estimated dates and provide updates to the supplier if there is a timing change.
A28: This section includes all relevant gateways and milestones in a given JLR Vehicle project. The JLR engineering shall include the relevant dates for each gateway or milestone to be used as a datum point for key supplier deliverables. Timelines and key date are required in order to fulfil the obligations of the seller in accordance with JLR-STN-19214 Global Terms and Conditions for Engineering Services, Section 3(c). The Jaguar Land Rover Lead Engineer is permitted to append a current Vehicle Program Framework (VPF) Document which outlines all relevant gateway and milestone dates, however it is recommended to complete the Timing Chart defined on the next page. Additional timing requirements can be included below in the Vehicle Programme Framework.
A29: EPM.3 Vehicle Programme Framework
A31: VEHICLE PROGRAMME FRAMEWORK
B32: CODE | C32: NAME | E32: TYPE | F32: DATE | G32: NOTES
A33: STRATEGY | B33: KO | C33: KICK OFF | E33: GATEWAY | F33: 45715
B34: PD | C34: PROG. DEFINITION | E34: GATEWAY | F34: 45729
B35: PS | C35: PROG. STRATEGY | E35: GATEWAY | F35: 45827
B36: PSC | C36: PROG. STRATEGY CONFIRMED | E36: GATEWAY | F36: 46007
A37: DELIVERY | B37: CC | C37: CONTRACT CHECKPOINT | E37: GATEWAY | F37: 46199
B38: FR | C38: FINANCIAL RELEASE | E38: GATEWAY | F38: 46311
B39: PR | C39: PRODUCTION RELEASE | E39: GATEWAY | F39: 46428
A40: LAUNCH | B40: PRC | C40: PRODUCTION RELEASE COMPLETION | E40: MILESTONE | F40: 46478
B41: LRR 1 | C41: VB READINESS | E41: MILESTONE | F41: 46541
B42: LRR 2 | C42: PLANT HANDOVER | E42: MILESTONE | F42: 46716
B43: CSO | C43: COMPONENT SIGN OFF | E43: MILESTONE | F43: 46730
B44: VSSO | C44: VEHICLE & SYSTEM SIGN OFF | E44: MILESTONE | F44: 46870
B45: LRR 3 | C45: PROCEED TO LAUNCH PRODUCTION | E45: GATEWAY | F45: 46884
B46: LRR 4 | C46: OPEN CUSTOMER SALEABLE ORDER CALL | E46: MILESTONE | F46: 47045
B47: FESO | C47: FINAL ENG. SIGN OFF | E47: MILESTONE | F47: 47010
...

Sheet Service Requirements
A1: Service Requirements
A2: This section contains the service requirements for the commodity that the supplier shall agree to. Jaguar Land Rover and the Supplier shall agree and understand that service requirements, including parts volume of parts, can change throughout the life of the product. Both parties shall communicate changes in writing in accordance with the Global Terms and Conditions for Engineering Services, JLR-STN-19214 and Global Terms and Conditions for Production Purchasing, JLR-STN-18499. The Lead Engineer must complete all fields with the guidance of the Service Commodity Lead, to ensure commodity-specific requirements are included where applicable. The Supplier must review the Jaguar Land Rover Aftermarket Parts and Accessories, JLR-EXP-570156. THIS SECTION IS MANDATORY. CONTACT MARK HARDY (MHARDY28) FOR DIRECTION TO THE SERVICE COMMODITY LEAD.
A4: SSR.1 General Service Requirements
A6: 1.1 Ease of Maintenance and Cost of Ownership
A7: Design all systems, components and levels of assembly to facilitate repairs identified within the Retailer Repair Procedures/Workshop Manual for ease of maintenance and/or repair at a competitive cost, and to meet programme serviceability cost of ownership (COO) targets. Where relevant, commodity must be compatible with existing consumables (e.g. oil grade, hydraulic fluid). There shall be no increase in PDI complexity or time.
A8: Notes and Bespoke Requirements (JLR Lead Engineer input only)
A9: Not Applicable
A11: 1.2 Serialization and As-Built Data
A12: Where applicable, provide serialization and as-built data for all applicable parts/systems in a format readily compatible with JLR systems. For commodities with key code functionality, ensure underlying algorithms are available to JLR lock database and demonstrate how these will be subsequently maintained.
A14: Notes and Bespoke Requirements (JLR Lead Engineer input only)
A15: Not Applicable
A17: 1.3 Repair and Replacement Procedures
... A39: Not Applicable
E41: END OF SECTION

Sheet Technical Requirements
A1: Technical Requirements
A2: This section contains the technical requirements and expectations for the commodity that the supplier shall agree to. This section contains high-level design information, commodity information, system design information and detailed technical requirements. Jaguar Land Rover may provide a Product Design Specification (PDS) in lieu of technical information in this section of the Statement of Work. A PDS is considered a Supporting Document to the Statement of Work and does not supersede or replace Statement of Work (JLR-TMP-557249). NOTE: REFER TO APPENDIX C. STANDARDS AND SUPPORTING DOCUMENTS FOR ALL ENGINEERING STANDARDS
A3: ETR.1 Product Definition Sheet
A4: Will Jaguar Land Rover issue a PDS to the supplier? | F4: YES | H4: Document Name
A6: ETR.2 Technical and System Information
A8: TECHNICAL OVERVIEW
A9: The parts contained within this eSOW are make to print floor access panel which provides access to an area of the fuel system, and provide a walkthrough floor for the 3rd row.
A11: SYSTEM OVERVIEW
A12: System interfaces: Main Floor Carpet, BIW
A14: SYSTEM CONTEXT
A15: The parts within this eSOW will interface and join to main floor carpet and BIW brackets.
A17: SYSTEM BEHAVIOURS
A18: Components shall be within tolerance to fit within the vehicle
A20: SYSTEM USE CASE
A21: Not Applicable
A22: ETR.3 Technical Targets and Attributes
A24: PANEL REF | B24: TECHNICAL ATTRIBUTE | E24: DESCRIPTION / TARGET / ATTRIBUTE | I24: CLASS. / CATEGORY / DELTA / SCORE
A25: AMS | B25: VTSO - AMS | E25: Not Applicable
A26: A1a | B26: Passive Safety | E26: Not Applicable
A27: A1b | B27: Perceived Quality | E27: Provide good percieved quality of part
A28: A1c | B28: Climate & Interior Air Quality | E28: Deliver parts within VOC limits and odor limits
A29: A1d | B29: Lighting | E29: Not Applicable
A30: A1e | B30: Sustainability | E30: Meet part recyclability requirement
A31: A2 | B31: Human Factors | E31: Not Applicable
A32: A3 | B32: Infotainment and Connectivity | E32: Not Applicable
A33: A4a | B33: Driving Dynamics | E33: Not Applicable
A34: A4b | B34: Brakes Engineering Attributes | E34: Not Applicable
A35: A4c | B35: Off Road & All Road Capability | E35: Not Applicable
A36: A5a | B36: Product Efficiency | E36: Not Applicable
... A50: VE | B50: Panel Owner | E50: Not Applicable
A51: ETR.4 Diagrams
A52: This section defines the system functional and Boundary Diagrams.
A53: FUNCTIONAL DIAGRAM
A56: BOUNDARY DIAGRAM
A58: ETR.5 Commodity Documents
A59: JLR, with support of the supplier, shall specify all drawings, documents and other technical information that the supplier is required to deliver in the table below.
A60: CoC / COMMODITY DOCUMENTS | D60: APPLICABLE | E60: LEVEL | F60: REVISION | G60: DATE | H60: MATERIAL DESCRIPTION
A61: Assembly Aids, Fixture/ Tools | D61: YES | E61: 1 | H61: Level 1 materials describe the geometric and functional attributes of the commodity (part), and how that part meets JLR's specifications and interacts with other vehicle components. At a minimum, the supplier must provide this information on Level One drawings unless otherwise approved by JLR. All Level One materials can be freely used by JLR without restriction.
A62: Component Package Drawings | D62: NO | E62: 1
A63: Component Part Drawings | D63: NO | E63: 1
...

Sheet Hardware & CAD
A1: Hardware and CAD/CAE
A2: This section contains all hardware, CAD and CAE requirements for the commodity.
A3: CAD.1 CAD and CAE Requirements
A4: This section defines which organisation is responsible for CAD design and CAE requirements. For CAD Exchange Methods and associated licenses refer to Front Matter, Page 3.
A5: SUPPLIER CATEGORY: | D5: ='Front Matter'!I8 -> Make to Print | J5: APPLICABILITY
A6: Is the supplier responsible for the design of the part and have sole design responsibility? | J6: NO
A7: Is the responsibility for the design of the part shared between the supplier and JLR? | J7: NO
A8: Does JLR own the design, and have design responsibility where the supplier is responsible for the manufacture of the part? | J8: YES
A10: CAD.2 CAD Releasing Requirements
A11: All New Tool End Items (NTEI) shall be mastered supporting Model Based Definition (MBD). Model Based Definition is an annotated model and its associated data elements that define the product in a manner that can be used effectively without a drawing graphic sheet. The goal of MBD is to provide complete Technical Product Specification (TPS) to downstream users and systems for the lifecycle of the product. This means all required engineering information is communicated from one source, the annotated model. Consistency is needed in the creation and presentation of each product to ensure information is communicated effectively.
A12: RELEASE TYPE | E12: USE CASE | J12: APPLICABILITY
A13: CTM (CAD The Master) | E13: For New Tool End (Engineering) Items (NTEI) | J13: YES
A14: DTMC (Drawing The Master w/CAD | E14: For Carry Over or Modified Parts | J14: NO
A15: DTM (Drawing The Master) | E15: For Carry Over or Modified Parts | J15: NO
A16: CAD Assembly Model Tech. Specification | E16: For CAD To be released at Part Level | J16: NO
A17: CAD Assembly Kinematics | E17: For products with dynamic movement. Assemblies shall be provided that contain that kinematic movement and/or dynamic movement envelope. | J17: NO
A19: CAD.3 Technical Product Specification Requirements
A20: For 3D CAD Model, Technical Product Specification (TPS) only​. This relates to 3D CAD data in electronic format. There is no 2D drawing. ​ A 3D TPS shall conform to BS ISO 16792.​ The 3D TPS shall fully specify all geometry, datums, dimensions and tolerances in order to provide suitable and sufficient information to manufacture and verify the workpiece. A 3D TPS shall consist of 3D model information only. The 3D model(s) shall provide the CAD nominal geometry and sufficient datums, dimensions, tolerances and general notation necessary to provide suitable and sufficient information to manufacture and verify the required part.​
A21: CAD.4 CAE Virtual Engineering
A22: This section defines the Virtual Engineering (CAE) deliverables required to support the programme(s) noted above. The term CAE in this instance refers to all forms of CAA and includes the following: CFD, FE(A), MBS, 1D systems. All suppliers to Jaguar Land Rover programmes are obligated to support CAE requirements. This section shall be considered prior to the instruction to any supplier to commence CAE work on behalf of JLR. This document should be used to define the framework for CAE activity in the Engineering Statement of Work. Suppliers must submit all CAE data in a format that is compliant with JLR’s CAE strategy.
A23: CAD.5 Geometry Requirements
A24: This section defines which organisation is responsible for analysis and solid geometry design.
A26: RESPONSIBILITY | D26: APPLICABILITY | F26: Revision / Release Number / Calibration / Parameter Table I.D. | I26: Supplier Requires Boundary Diagram or Other NGD Data Types
A27: Supplier requires solid geometry | D27: YES
A29: CAD CREATION AND DELIVERY / TASK DESCRIPTION | I29: RESPONSIBILITY
A30: Creation and delivery of a CAE Finite Element meshed part from CAD (FE model build). | I30: JLR
A31: Creation and delivery of a 1D model and/or control system model(i.e. simulation model of the software that would eventually go into an ECU on a vehicle). | I31: JLR
A32: Execution of an existing method or capability in JLR to deliver some form of analysis report. | I32: JLR
A33: Development of a new simulation method or capability (Includes Capability projects). | I33: JLR
A35: CAD.6 Virtual Engineering Responsibilities
A36: This section defines the JLR and Supplier task and associated responsibilities for Virtual Engineering requirements.
A37: Task Description (Defined by Jaguar Land Rover) | F37: Responsibility for Supplier | J37: APPLICABILITY
A38: Define the nature and purpose of the CAE activity. | F38: None | J38: YES
A39: Specify the element(s) of the CAE activity to be delivered. | F39: None | J39: YES
A40: Specify the further sharing requirement. If the deliverable of this task includes a model the all users shall be identified and listed below; 1. Internal Users of the open model 2. Third party Users 3. Location (UK, Gaydon, China) | F40: Where the deliverable of the task is either in full or in part a CAE model; The model requester (Supplier Engineer) in conjunction with the Virtual Hub department at JLR must disclose the requirement to distribute the functionality of that model to JLR and to third parties*. | J40: YES
A41: * Third party in this case only refers to and is limited to; 1. Research Partners to JLR with an existing supplier relationship 2. Other suppliers to JLR with an existing supplier relationship who require, and may be expected to provide justification for, access to the design information to support any project as agreed by JLR.
A43: CAD.6.1 Virtual Engineering Responsibilities - Scope of CAD
A45: Task Description (Defined by Jaguar Land Rover) | E45: Responsibility for Supplier | J45: APPLICABILITY
A46: Provide an detailed description of the CAE model requirement. For 1D Systems Models; Download and complete the Model Specification Document Template. | E46: Understand, agree and demonstrate the ability to generate the requested model. The supplier shall prepare evidence to support their ability to create the requested model. | J46: YES
A47: This section is only applicable for 1D System Models. 1. Provide an detailed description of the inputs and outputs for 1D system model. Refer to 1D Technical Library, System IO Standard for 1D Models for the correct standards. 2. Provide the JLR Naming Standard and associated documents and naming variables. Refer to the JLR Signal Naming Convention portal for the correct standards and guidelines. 3. If the simulation modelling requires the application of Model Based Design (MBD) methods and automatic code generation then, refer to MISRA AC GMG for industry standards and guidelines. | E47: Collate, review and understand the engineering and industry standards which have been identified and provided by JLR (through any portal or communication channel) and make sure that the model requirements, and delivered product align to all relevant sections of the engineering and industry standards. Refer to Section E.5 - Engineering and Industry Standards for more information. | J47: YES
...

Sheet Appendix A. RASIC
A1: Appendix A. RASIC
B3: SUPPLIER CATEGORY
B4: ='Front Matter'!I8 -> Make to Print
B6: This section defines all tasks, roles and responsibilities to be agreed between JLR and the supplier. Deviations or changes to the tasks defined in this section are not permitted and must be recorded in the Supplemental Terms and Conditions. The Lead Engineering can create additional Tasks and associated RASIC in Appendix B. RASIC Additions. A RASIC is mandatory for all sourcing projects.
A8: [PM] PROGRAMME MANAGEMENT | K8: APPLICABLE TO SOURCING PROJECT: | O8: APPLICABLE
A9: ID | B9: DESCRIPTION OF TASK | K9: Lead | L9: R | M9: A | N9: S | O9: I | P9: C
A10: =IF($B$4="Assembly or Component Provider",DATA_RASIC_DESC!A3,IF($B$4="Consultancy Component Provider",DATA_RASIC_DESC!A3,IF($B$4="Make to Print",DATA_RASIC_DESC!A3,IF($B$4="Engineering Service Provider",DATA_RASIC_DESC!A3,IF($B$4="Full System Provider",DATA_RASIC_DESC!A3,IF($B$4="ESP_DOOR TRIM",DATA_RASIC_DESC!D3,IF($B$4="ESP_Partner_LEVEL_01",DATA_RASIC_DESC!G3,""))))))) -> PM.1 | B10: =IF($B$4="Assembly or Component Provider",DATA_RASIC_DESC!B3,IF($B$4="Consultancy Component Provider",DATA_RASIC_DESC!B3,IF($B$4="Make to Print",DATA_RASIC_DESC!B3,IF($B$4="Engineering Service Provider",DATA_RASIC_DESC!B3,IF($B$4="Full System Provider",DATA_RASIC_DESC!B3,IF($B$4="ESP_DOOR TRIM",DATA_RASIC_DESC!E3,IF($B$4="ESP_Partner_LEVEL_01",DATA_RASIC_DESC!H3,""))))))) -> Provide communication as appropriate to all affected functions | K10: =IF($B$4="Assembly or Component Provider",DATA_RASIC!Q3,IF($B$4="Consultancy Component Provider",DATA_RASIC!X3,IF($B$4="Make to Print",DATA_RASIC!AE3,IF($B$4="Engineering Service Provider",DATA_RASIC!C3,IF($B$4="Full System Provider",DATA_RASIC!J3,IF($B$4="ESP_DOOR TRIM",DATA_RASIC!AL3,IF($B$4="ESP_Partner_LEVEL_01",DATA_RASIC!AS3,""))))))) -> JLR | L10: =IF($B$4="Assembly or Component Provider",DATA_RASIC!R3,IF($B$4="Consultancy Component Provider",DATA_RASIC!Y3,IF($B$4="Make to Print",DATA_RASIC!AF3,IF($B$4="Engineering Service Provider",DATA_RASIC!D3,IF($B$4="Full System Provider",DATA_RASIC!K3,IF($B$4="ESP_DOOR TRIM",DATA_RASIC!AM3,IF($B$4="ESP_Partner_LEVEL_01",DATA_RASIC!AT3,""))))))) -> JLR | M10: =IF($B$4="Assembly or Component Provider",DATA_RASIC!S3,IF($B$4="Consultancy Component Provider",DATA_RASIC!Z3,IF($B$4="Make to Print",DATA_RASIC!AG3,IF($B$4="Engineering Service Provider",DATA_RASIC!E3,IF($B$4="Full System Provider",DATA_RASIC!L3,IF($B$4="ESP_DOOR TRIM",DATA_RASIC!AN3,IF($B$4="ESP_Partner_LEVEL_01",DATA_RASIC!AU3,""))))))) -> JLR | N10: =IF($B$4="Assembly or Component Provider",DATA_RASIC!T3,IF($B$4="Consultancy Component Provider",DATA_RASIC!AA3,IF($B$4="Make to Print",DATA_RASIC!AH3,IF($B$4="Engineering Service Provider",DATA_RASIC!F3,IF($B$4="Full System Provider",DATA_RASIC!M3,IF($B$4="ESP_DOOR TRIM",DATA_RASIC!AO3,IF($B$4="ESP_Partner_LEVEL_01",DATA_RASIC!AV3,""))))))) -> - | O10: =IF($B$4="Assembly or Component Provider",DATA_RASIC!U3,IF($B$4="Consultancy Component Provider",DATA_RASIC!AB3,IF($B$4="Make to Print",DATA_RASIC!AI3,IF($B$4="Engineering Service Provider",DATA_RASIC!G3,IF($B$4="Full System Provider",DATA_RASIC!N3,IF($B$4="ESP_DOOR TRIM",DATA_RASIC!AP3,IF($B$4="ESP_Partner_LEVEL_01",DATA_RASIC!AW3,""))))))) -> SE | P10: =IF($B$4="Assembly or Component Provider",DATA_RASIC!V3,IF($B$4="Consultancy Component Provider",DATA_RASIC!AC3,IF($B$4="Make to Print",DATA_RASIC!AJ3,IF($B$4="Engineering Service Provider",DATA_RASIC!H3,IF($B$4="Full System Provider",DATA_RASIC!O3,IF($B$4="ESP_DOOR TRIM",DATA_RASIC!AQ3,IF($B$4="ESP_Partner_LEVEL_01",DATA_RASIC!AX3,""))))))) -> -
A11: =IF($B$4="Assembly or Component Provider",DATA_RASIC_DESC!A4,IF($B$4="Consultancy Component Provider",DATA_RASIC_DESC!A4,IF($B$4="Make to Print",DATA_RASIC_DESC!A4,IF($B$4="Engineering Service Provider",DATA_RASIC_DESC!A4,IF($B$4="Full System Provider",DATA_RASIC_DESC!A4,IF($B$4="ESP_DOOR TRIM",DATA_RASIC_DESC!D4,IF($B$4="ESP_Partner_LEVEL_01",DATA_RASIC_DESC!G4,""))))))) -> PM.2 | B11: =IF($B$4="Assembly or Component Provider",DATA_RASIC_DESC!B4,IF($B$4="Consultancy Component Provider",DATA_RASIC_DESC!B4,IF($B$4="Make to Print",DATA_RASIC_DESC!B4,IF($B$4="Engineering Service Provider",DATA_RASIC_DESC!B4,IF($B$4="Full System Provider",DATA_RASIC_DESC!B4,IF($B$4="ESP_DOOR TRIM",DATA_RASIC_DESC!E4,IF($B$4="ESP_Partner_LEVEL_01",DATA_RASIC_DESC!H4,""))))))) -> Develop an Early Sourcing Work plan for Programme team consensus | K11: =IF($B$4="Assembly or Component Provider",DATA_RASIC!Q4,IF($B$4="Consultancy Component Provider",DATA_RASIC!X4,IF($B$4="Make to Print",DATA_RASIC!AE4,IF($B$4="Engineering Service Provider",DATA_RASIC!C4,IF($B$4="Full System Provider",DATA_RASIC!J4,IF($B$4="ESP_DOOR TRIM",DATA_RASIC!AL4,IF($B$4="ESP_Partner_LEVEL_01",DATA_RASIC!AS4,""))))))) -> JLR | L11: =IF($B$4="Assembly or Component Provider",DATA_RASIC!R4,IF($B$4="Consultancy Component Provider",DATA_RASIC!Y4,IF($B$4="Make to Print",DATA_RASIC!AF4,IF($B$4="Engineering Service Provider",DATA_RASIC!D4,IF($B$4="Full System Provider",DATA_RASIC!K4,IF($B$4="ESP_DOOR TRIM",DATA_RASIC!AM4,IF($B$4="ESP_Partner_LEVEL_01",DATA_RASIC!AT4,""))))))) -> JLR | M11: =IF($B$4="Assembly or Component Provider",DATA_RASIC!S4,IF($B$4="Consultancy Component Provider",DATA_RASIC!Z4,IF($B$4="Make to Print",DATA_RASIC!AG4,IF($B$4="Engineering Service Provider",DATA_RASIC!E4,IF($B$4="Full System Provider",DATA_RASIC!L4,IF($B$4="ESP_DOOR TRIM",DATA_RASIC!AN4,IF($B$4="ESP_Partner_LEVEL_01",DATA_RASIC!AU4,""))))))) -> JLR | N11: =IF($B$4="Assembly or Component Provider",DATA_RASIC!T4,IF($B$4="Consultancy Component Provider",DATA_RASIC!AA4,IF($B$4="Make to Print",DATA_RASIC!AH4,IF($B$4="Engineering Service Provider",DATA_RASIC!F4,IF($B$4="Full System Provider",DATA_RASIC!M4,IF($B$4="ESP_DOOR TRIM",DATA_RASIC!AO4,IF($B$4="ESP_Partner_LEVEL_01",DATA_RASIC!AV4,""))))))) -> - | O11: =IF($B$4="Assembly or Component Provider",DATA_RASIC!U4,IF($B$4="Consultancy Component Provider",DATA_RASIC!AB4,IF($B$4="Make to Print",DATA_RASIC!AI4,IF($B$4="Engineering Service Provider",DATA_RASIC!G4,IF($B$4="Full System Provider",DATA_RASIC!N4,IF($B$4="ESP_DOOR TRIM",DATA_RASIC!AP4,IF($B$4="ESP_Partner_LEVEL_01",DATA_RASIC!AW4,""))))))) -> SE | P11: =IF($B$4="Assembly or Component Provider",DATA_RASIC!V4,IF($B$4="Consultancy Component Provider",DATA_RASIC!AC4,IF($B$4="Make to Print",DATA_RASIC!AJ4,IF($B$4="Engineering Service Provider",DATA_RASIC!H4,IF($B$4="Full System Provider",DATA_RASIC!O4,IF($B$4="ESP_DOOR TRIM",DATA_RASIC!AQ4,IF($B$4="ESP_Partner_LEVEL_01",DATA_RASIC!AX4,""))))))) -> -
A12: =IF($B$4="Assembly or Component Provider",DATA_RASIC_DESC!A5,IF($B$4="Consultancy Component Provider",DATA_RASIC_DESC!A5,IF($B$4="Make to Print",DATA_RASIC_DESC!A5,IF($B$4="Engineering Service Provider",DATA_RASIC_DESC!A5,IF($B$4="Full System Provider",DATA_RASIC_DESC!A5,IF($B$4="ESP_DOOR TRIM",DATA_RASIC_DESC!D5,IF($B$4="ESP_Partner_LEVEL_01",DATA_RASIC_DESC!G5,""))))))) -> PM.3 | B12: =IF($B$4="Assembly or Component Provider",DATA_RASIC_DESC!B5,IF($B$4="Consultancy Component Provider",DATA_RASIC_DESC!B5,IF($B$4="Make to Print",DATA_RASIC_DESC!B5,IF($B$4="Engineering Service Provider",DATA_RASIC_DESC!B5,IF($B$4="Full System Provider",DATA_RASIC_DESC!B5,IF($B$4="ESP_DOOR TRIM",DATA_RASIC_DESC!E5,IF($B$4="ESP_Partner_LEVEL_01",DATA_RASIC_DESC!H5,""))))))) -> Appoint a Project Leader & functional Manager of Jaguar Land Rover | K12: =IF($B$4="Assembly or Component Provider",DATA_RASIC!Q5,IF($B$4="Consultancy Component Provider",DATA_RASIC!X5,IF($B$4="Make to Print",DATA_RASIC!AE5,IF($B$4="Engineering Service Provider",DATA_RASIC!C5,IF($B$4="Full System Provider",DATA_RASIC!J5,IF($B$4="ESP_DOOR TRIM",DATA_RASIC!AL5,IF($B$4="ESP_Partner_LEVEL_01",DATA_RASIC!AS5,""))))))) -> JLR | L12: =IF($B$4="Assembly or Component Provider",DATA_RASIC!R5,IF($B$4="Consultancy Component Provider",DATA_RASIC!Y5,IF($B$4="Make to Print",DATA_RASIC!AF5,IF($B$4="Engineering Service Provider",DATA_RASIC!D5,IF($B$4="Full System Provider",DATA_RASIC!K5,IF($B$4="ESP_DOOR TRIM",DATA_RASIC!AM5,IF($B$4="ESP_Partner_LEVEL_01",DATA_RASIC!AT5,""))))))) -> JLR | M12: =IF($B$4="Assembly or Component Provider",DATA_RASIC!S5,IF($B$4="Consultancy Component Provider",DATA_RASIC!Z5,IF($B$4="Make to Print",DATA_RASIC!AG5,IF($B$4="Engineering Service Provider",DATA_RASIC!E5,IF($B$4="Full System Provider",DATA_RASIC!L5,IF($B$4="ESP_DOOR TRIM",DATA_RASIC!AN5,IF($B$4="ESP_Partner_LEVEL_01",DATA_RASIC!AU5,""))))))) -> JLR | N12: =IF($B$4="Assembly or Component Provider",DATA_RASIC!T5,IF($B$4="Consultancy Component Provider",DATA_RASIC!AA5,IF($B$4="Make to Print",DATA_RASIC!AH5,IF($B$4="Engineering Service Provider",DATA_RASIC!F5,IF($B$4="Full System Provider",DATA_RASIC!M5,IF($B$4="ESP_DOOR TRIM",DATA_RASIC!AO5,IF($B$4="ESP_Partner_LEVEL_01",DATA_RASIC!AV5,""))))))) -> - | O12: =IF($B$4="Assembly or Component Provider",DATA_RASIC!U5,IF($B$4="Consultancy Component Provider",DATA_RASIC!AB5,IF($B$4="Make to Print",DATA_RASIC!AI5,IF($B$4="Engineering Service Provider",DATA_RASIC!G5,IF($B$4="Full System Provider",DATA_RASIC!N5,IF($B$4="ESP_DOOR TRIM",DATA_RASIC!AP5,IF($B$4="ESP_Partner_LEVEL_01",DATA_RASIC!AW5,""))))))) -> SE | P12: =IF($B$4="Assembly or Component Provider",DATA_RASIC!V5,IF($B$4="Consultancy Component Provider",DATA_RASIC!AC5,IF($B$4="Make to Print",DATA_RASIC!AJ5,IF($B$4="Engineering Service Provider",DATA_RASIC!H5,IF($B$4="Full System Provider",DATA_RASIC!O5,IF($B$4="ESP_DOOR TRIM",DATA_RASIC!AQ5,IF($B$4="ESP_Partner_LEVEL_01",DATA_RASIC!AX5,""))))))) -> -
A13: =IF($B$4="Assembly or Component Provider",DATA_RASIC_DESC!A6,IF($B$4="Consultancy Component Provider",DATA_RASIC_DESC!A6,IF($B$4="Make to Print",DATA_RASIC_DESC!A6,IF($B$4="Engineering Service Provider",DATA_RASIC_DESC!A6,IF($B$4="Full System Provider",DATA_RASIC_DESC!A6,IF($B$4="ESP_DOOR TRIM",DATA_RASIC_DESC!D6,IF($B$4="ESP_Partner_LEVEL_01",DATA_RASIC_DESC!G6,""))))))) -> PM.4 | B13: =IF($B$4="Assembly or Component Provider",DATA_RASIC_DESC!B6,IF($B$4="Consultancy Component Provider",DATA_RASIC_DESC!B6,IF($B$4="Make to Print",DATA_RASIC_DESC!B6,IF($B$4="Engineering Service Provider",DATA_RASIC_DESC!B6,IF($B$4="Full System Provider",DATA_RASIC_DESC!B6,IF($B$4="ESP_DOOR TRIM",DATA_RASIC_DESC!E6,IF($B$4="ESP_Partner_LEVEL_01",DATA_RASIC_DESC!H6,""))))))) -> Establish Programme Management Teams (PMTs) as required and support supplier lead Programme Module Team | K13: =IF($B$4="Assembly or Component Provider",DATA_RASIC!Q6,IF($B$4="Consultancy Component Provider",DATA_RASIC!X6,IF($B$4="Make to Print",DATA_RASIC!AE6,IF($B$4="Engineering Service Provider",DATA_RASIC!C6,IF($B$4="Full System Provider",DATA_RASIC!J6,IF($B$4="ESP_DOOR TRIM",DATA_RASIC!AL6,IF($B$4="ESP_Partner_LEVEL_01",DATA_RASIC!AS6,""))))))) -> JLR | L13: =IF($B$4="Assembly or Component Provider",DATA_RASIC!R6,IF($B$4="Consultancy Component Provider",DATA_RASIC!Y6,IF($B$4="Make to Print",DATA_RASIC!AF6,IF($B$4="Engineering Service Provider",DATA_RASIC!D6,IF($B$4="Full System Provider",DATA_RASIC!K6,IF($B$4="ESP_DOOR TRIM",DATA_RASIC!AM6,IF($B$4="ESP_Partner_LEVEL_01",DATA_RASIC!AT6,""))))))) -> JLR | M13: =IF($B$4="Assembly or Component Provider",DATA_RASIC!S6,IF($B$4="Consultancy Component Provider",DATA_RASIC!Z6,IF($B$4="Make to Print",DATA_RASIC!AG6,IF($B$4="Engineering Service Provider",DATA_RASIC!E6,IF($B$4="Full System Provider",DATA_RASIC!L6,IF($B$4="ESP_DOOR TRIM",DATA_RASIC!AN6,IF($B$4="ESP_Partner_LEVEL_01",DATA_RASIC!AU6,""))))))) -> JLR | N13: =IF($B$4="Assembly or Component Provider",DATA_RASIC!T6,IF($B$4="Consultancy Component Provider",DATA_RASIC!AA6,IF($B$4="Make to Print",DATA_RASIC!AH6,IF($B$4="Engineering Service Provider",DATA_RASIC!F6,IF($B$4="Full System Provider",DATA_RASIC!M6,IF($B$4="ESP_DOOR TRIM",DATA_RASIC!AO6,IF($B$4="ESP_Partner_LEVEL_01",DATA_RASIC!AV6,""))))))) -> SE | O13: =IF($B$4="Assembly or Component Provider",DATA_RASIC!U6,IF($B$4="Consultancy Component Provider",DATA_RASIC!AB6,IF($B$4="Make to Print",DATA_RASIC!AI6,IF($B$4="Engineering Service Provider",DATA_RASIC!G6,IF($B$4="Full System Provider",DATA_RASIC!N6,IF($B$4="ESP_DOOR TRIM",DATA_RASIC!AP6,IF($B$4="ESP_Partner_LEVEL_01",DATA_RASIC!AW6,""))))))) -> - | P13: =IF($B$4="Assembly or Component Provider",DATA_RASIC!V6,IF($B$4="Consultancy Component Provider",DATA_RASIC!AC6,IF($B$4="Make to Print",DATA_RASIC!AJ6,IF($B$4="Engineering Service Provider",DATA_RASIC!H6,IF($B$4="Full System Provider",DATA_RASIC!O6,IF($B$4="ESP_DOOR TRIM",DATA_RASIC!AQ6,IF($B$4="ESP_Partner_LEVEL_01",DATA_RASIC!AX6,""))))))) -> -
A14: =IF($B$4="Assembly or Component Provider",DATA_RASIC_DESC!A7,IF($B$4="Consultancy Component Provider",DATA_RASIC_DESC!A7,IF($B$4="Make to Print",DATA_RASIC_DESC!A7,IF($B$4="Engineering Service Provider",DATA_RASIC_DESC!A7,IF($B$4="Full System Provider",DATA_RASIC_DESC!A7,IF($B$4="ESP_DOOR TRIM",DATA_RASIC_DESC!D7,IF($B$4="ESP_Partner_LEVEL_01",DATA_RASIC_DESC!G7,""))))))) -> PM.5 | B14: =IF($B$4="Assembly or Component Provider",DATA_RASIC_DESC!B7,IF($B$4="Consultancy Component Provider",DATA_RASIC_DESC!B7,IF($B$4="Make to Print",DATA_RASIC_DESC!B7,IF($B$4="Engineering Service Provider",DATA_RASIC_DESC!B7,IF($B$4="Full System Provider",DATA_RASIC_DESC!B7,IF($B$4="ESP_DOOR TRIM",DATA_RASIC_DESC!E7,IF($B$4="ESP_Partner_LEVEL_01",DATA_RASIC_DESC!H7,""))))))) -> Create commodity work plans to supplement the Programme specific VPP | K14: =IF($B$4="Assembly or Component Provider",DATA_RASIC!Q7,IF($B$4="Consultancy Component Provider",DATA_RASIC!X7,IF($B$4="Make to Print",DATA_RASIC!AE7,IF($B$4="Engineering Service Provider",DATA_RASIC!C7,IF($B$4="Full System Provider",DATA_RASIC!J7,IF($B$4="ESP_DOOR TRIM",DATA_RASIC!AL7,IF($B$4="ESP_Partner_LEVEL_01",DATA_RASIC!AS7,""))))))) -> JLR | L14: =IF($B$4="Assembly or Component Provider",DATA_RASIC!R7,IF($B$4="Consultancy Component Provider",DATA_RASIC!Y7,IF($B$4="Make to Print",DATA_RASIC!AF7,IF($B$4="Engineering Service Provider",DATA_RASIC!D7,IF($B$4="Full System Provider",DATA_RASIC!K7,IF($B$4="ESP_DOOR TRIM",DATA_RASIC!AM7,IF($B$4="ESP_Partner_LEVEL_01",DATA_RASIC!AT7,""))))))) -> JLR | M14: =IF($B$4="Assembly or Component Provider",DATA_RASIC!S7,IF($B$4="Consultancy Component Provider",DATA_RASIC!Z7,IF($B$4="Make to Print",DATA_RASIC!AG7,IF($B$4="Engineering Service Provider",DATA_RASIC!E7,IF($B$4="Full System Provider",DATA_RASIC!L7,IF($B$4="ESP_DOOR TRIM",DATA_RASIC!AN7,IF($B$4="ESP_Partner_LEVEL_01",DATA_RASIC!AU7,""))))))) -> JLR | N14: =IF($B$4="Assembly or Component Provider",DATA_RASIC!T7,IF($B$4="Consultancy Component Provider",DATA_RASIC!AA7,IF($B$4="Make to Print",DATA_RASIC!AH7,IF($B$4="Engineering Service Provider",DATA_RASIC!F7,IF($B$4="Full System Provider",DATA_RASIC!M7,IF($B$4="ESP_DOOR TRIM",DATA_RASIC!AO7,IF($B$4="ESP_Partner_LEVEL_01",DATA_RASIC!AV7,""))))))) -> SE | O14: =IF($B$4="Assembly or Component Provider",DATA_RASIC!U7,IF($B$4="Consultancy Component Provider",DATA_RASIC!AB7,IF($B$4="Make to Print",DATA_RASIC!AI7,IF($B$4="Engineering Service Provider",DATA_RASIC!G7,IF($B$4="Full System Provider",DATA_RASIC!N7,IF($B$4="ESP_DOOR TRIM",DATA_RASIC!AP7,IF($B$4="ESP_Partner_LEVEL_01",DATA_RASIC!AW7,""))))))) -> - | P14: =IF($B$4="Assembly or Component Provider",DATA_RASIC!V7,IF($B$4="Consultancy Component Provider",DATA_RASIC!AC7,IF($B$4="Make to Print",DATA_RASIC!AJ7,IF($B$4="Engineering Service Provider",DATA_RASIC!H7,IF($B$4="Full System Provider",DATA_RASIC!O7,IF($B$4="ESP_DOOR TRIM",DATA_RASIC!AQ7,IF($B$4="ESP_Partner_LEVEL_01",DATA_RASIC!AX7,""))))))) -> -
A15: =IF($B$4="Assembly or Component Provider",DATA_RASIC_DESC!A8,IF($B$4="Consultancy Component Provider",DATA_RASIC_DESC!A8,IF($B$4="Make to Print",DATA_RASIC_DESC!A8,IF($B$4="Engineering Service Provider",DATA_RASIC_DESC!A8,IF($B$4="Full System Provider",DATA_RASIC_DESC!A8,IF($B$4="ESP_DOOR TRIM",DATA_RASIC_DESC!D8,IF($B$4="ESP_Partner_LEVEL_01",DATA_RASIC_DESC!G8,""))))))) -> PM.6 | B15: =IF($B$4="Assembly or Component Provider",DATA_RASIC_DESC!B8,IF($B$4="Consultancy Component Provider",DATA_RASIC_DESC!B8,IF($B$4="Make to Print",DATA_RASIC_DESC!B8,IF($B$4="Engineering Service Provider",DATA_RASIC_DESC!B8,IF($B$4="Full System Provider",DATA_RASIC_DESC!B8,IF($B$4="ESP_DOOR TRIM",DATA_RASIC_DESC!E8,IF($B$4="ESP_Partner_LEVEL_01",DATA_RASIC_DESC!H8,""))))))) -> Provide access to Jaguar Land Rover's data systems which are required for the Programme. e.g. / WERS CONCERN , NOTICE and ALERT system to allow the supplier to generate the necessary data to support Jaguar Land Rover's release system | K15: =IF($B$4="Assembly or Component Provider",DATA_RASIC!Q8,IF($B$4="Consultancy Component Provider",DATA_RASIC!X8,IF($B$4="Make to Print",DATA_RASIC!AE8,IF($B$4="Engineering Service Provider",DATA_RASIC!C8,IF($B$4="Full System Provider",DATA_RASIC!J8,IF($B$4="ESP_DOOR TRIM",DATA_RASIC!AL8,IF($B$4="ESP_Partner_LEVEL_01",DATA_RASIC!AS8,""))))))) -> JLR | L15: =IF($B$4="Assembly or Component Provider",DATA_RASIC!R8,IF($B$4="Consultancy Component Provider",DATA_RASIC!Y8,IF($B$4="Make to Print",DATA_RASIC!AF8,IF($B$4="Engineering Service Provider",DATA_RASIC!D8,IF($B$4="Full System Provider",DATA_RASIC!K8,IF($B$4="ESP_DOOR TRIM",DATA_RASIC!AM8,IF($B$4="ESP_Partner_LEVEL_01",DATA_RASIC!AT8,""))))))) -> JLR | M15: =IF($B$4="Assembly or Component Provider",DATA_RASIC!S8,IF($B$4="Consultancy Component Provider",DATA_RASIC!Z8,IF($B$4="Make to Print",DATA_RASIC!AG8,IF($B$4="Engineering Service Provider",DATA_RASIC!E8,IF($B$4="Full System Provider",DATA_RASIC!L8,IF($B$4="ESP_DOOR TRIM",DATA_RASIC!AN8,IF($B$4="ESP_Partner_LEVEL_01",DATA_RASIC!AU8,""))))))) -> JLR | N15: =IF($B$4="Assembly or Component Provider",DATA_RASIC!T8,IF($B$4="Consultancy Component Provider",DATA_RASIC!AA8,IF($B$4="Make to Print",DATA_RASIC!AH8,IF($B$4="Engineering Service Provider",DATA_RASIC!F8,IF($B$4="Full System Provider",DATA_RASIC!M8,IF($B$4="ESP_DOOR TRIM",DATA_RASIC!AO8,IF($B$4="ESP_Partner_LEVEL_01",DATA_RASIC!AV8,""))))))) -> - | O15: =IF($B$4="Assembly or Component Provider",DATA_RASIC!U8,IF($B$4="Consultancy Component Provider",DATA_RASIC!AB8,IF($B$4="Make to Print",DATA_RASIC!AI8,IF($B$4="Engineering Service Provider",DATA_RASIC!G8,IF($B$4="Full System Provider",DATA_RASIC!N8,IF($B$4="ESP_DOOR TRIM",DATA_RASIC!AP8,IF($B$4="ESP_Partner_LEVEL_01",DATA_RASIC!AW8,""))))))) -> SE | P15: =IF($B$4="Assembly or Component Provider",DATA_RASIC!V8,IF($B$4="Consultancy Component Provider",DATA_RASIC!AC8,IF($B$4="Make to Print",DATA_RASIC!AJ8,IF($B$4="Engineering Service Provider",DATA_RASIC!H8,IF($B$4="Full System Provider",DATA_RASIC!O8,IF($B$4="ESP_DOOR TRIM",DATA_RASIC!AQ8,IF($B$4="ESP_Partner_LEVEL_01",DATA_RASIC!AX8,""))))))) -> -
